Workbook
Name E: 'INPUT2 - Veh Sub-Syst Mass'!$B$262

Sheet Updates
C3: Date | D3: Updates | E3: Who
B4: V1.0 | C4: 44201 | D4: Initial release | E4: Hervé URVOY DE PORTZAMPARC
B5: V2.0 | C5: 44785 | D5: Excel document global review : - Inputs updated. - CoG formula updated. - Z CoG compared to groung new calculation. - Unsprung mass calculation added. - Check ased on P64 Bev done. | E5: Gilles PAPET
B6: V3.0 | C6: 44854 | D6: ? | E6: Gilles PAPET
B7: V4.0 | C7: 44854 | D7: ? | E7: Gilles PAPET
B8: V5.0 | C8: 44880 | D8: Formula correction : - Unsprung Twist beam calculation - CoG calculation (INPUT2 - Veh Sub-Syst Mass) | E8: Gilles PAPET
B9: V6.0 | C9: 44886 | D9: Update of engines generic CoG position. | E9: Gilles PAPET
B10: V7.0 | C10: 46106 | D10: Deleted : - Condenseur de clim (line 23) beacause doubling - Front engine : M4+RGM (line 88) beacause doubling Modified : - Formulas of CdG Durites (line 15), Liquide de refroidissement (line 16), FACADE (line 22), LIQUIDE REFROIDISSEMENT (line 24), MEAP/Ventilateur/Radiateur/Condenseur (X only, line 141) | E10: Laurent BOLIVAL

Sheet INPUT1 - Veh Geometry
B2: INPUTS SHEET :
B3: Yellow cells : A remplir avec le 5ème de ref ou données remontage véhicue remplacé / Fill with information from GAP or previous vehicule
B4: Orange cells : Pour info (ne pas toucher !!) / For Your Information (don't modify!!)
B5: Grey cells : Info non utile, ne pas remplir / Not used, do not fill
M6: Source Input : Qui? | N6: Quand? | O6: Commentaire
B7: Vehicle :
B8: Program / Project / Version : | H8: STLA-S | I8: J1X MHEV P2 FWD | J8: L2
B10: Inputs for GVW load case estimation : | H10: X(mm) | I10: Y (mm) | J10: Z(mm)
C11: Options : FRONT mass | G11: 1.3159445
C12: Options : REAR mass | G12: 54.688055
C13: Options : TOTAL mass | G13: =G11+G12 -> 56.004 | H13: =G12/G13*H33+H61 -> 2535.467 | I13: 0 | J13: 250
C14: Number of passengers | G14: 5
C15: Passenger mass : | G15: 75
G16: Total : | H16: X CoG : | I16: Mass Front : | J16: Mass Rear :
C17: - Row1 passengers repartition : | G17: =(IF('INPUT1 - Veh Geometry'!G14=0,0,IF('INPUT1 - Veh Geometry'!G14=1,1,IF('INPUT1 - Veh Geometry'!G14=2,2,2))))*'INPUT1 - Veh Geometry'!G15 -> 150 | H17: =H42 -> 1334 | I17: =G17-J17 -> 71.789773 | J17: =G17*(H17-$H$61)/$H$33 -> 78.210227
C18: - Row2 passengers repartition : | G18: =(IF(OR('INPUT1 - Veh Geometry'!G14=0,'INPUT1 - Veh Geometry'!G14=1,'INPUT1 - Veh Geometry'!G14=2),0,IF('INPUT1 - Veh Geometry'!G14=3,1,IF('INPUT1 - Veh Geometry'!G14=4,2,IF('INPUT1 - Veh Geometry'!G14=5,3,3)))))*'INPUT1 - Veh Geometry'!G15 -> 225 | H18: =H49 -> 2130 | I18: =G18-J18 -> 39.84375 | J18: =G18*(H18-$H$61)/$H$33 -> 185.15625
C19: - Row3 passengers repartition : | G19: =(IF(AND('INPUT1 - Veh Geometry'!G14>=0,'INPUT1 - Veh Geometry'!G14<=5),0,IF('INPUT1 - Veh Geometry'!G14=6,1,IF('INPUT1 - Veh Geometry'!G14=7,2,2))))*'INPUT1 - Veh Geometry'!G15 -> 0 | H19: =H52 -> 0 | I19: =G19-J19 -> 0 | J19: =G19*(H19-$H$61)/$H$33 -> 0
C20: - Global passengers : | I20: =SUM(I17:I19) -> 111.63352 | J20: =SUM(J17:J19) -> 263.36648
C21: EMC / After sale payload | G21: 40
G22: Total : | H22: X CoG : | I22: Mass Front : | J22: Mass Rear :
C23: - EMC repartition | G23: =G21 -> 40 | H23: =H57 -> 2750 | I23: =G23-J23 -> -2.3106061 | J23: =G23*(H23-$H$61)/$H$33 -> 42.310606
B25: Inputs for MREF load case estimation :
C26: Number of row1 passengers | G26: 2
C27: Mass of row1 passenger : | G27: 68
C28: Number of row2 passengers + Mass | G28: 2
C29: Mass of row1 passenger : ADULT / CHILDREN | G29: 68
C30: Luggage per passenger : | G30: 7
B32: Platform : | H32: X(mm) | I32: Y (mm) | J32: Z(mm)
C33: Empattement (mm) / wheelbase | H33: 2640 | L33: Données issues du 1/5e de ref / Inputs from the GAP (1/5e de ref) | M33: CHRISTOPHE KOTTMANN | N33: 46108
C34: Hauteur Vh en ODM / Vehicule Height in ODM | J34: 1650 | L34: Données issues du 1/5e de ref / Inputs from the GAP (1/5e de ref)
C35: PàF Av (mm) / Front OverHang | H35: 820 | L35: Données issues du 1/5e de ref / Inputs from the GAP (1/5e de ref)
C36: PàF Ar (mm) / Rear OverHang | H36: 700 | L36: Données issues du 1/5e de ref / Inputs from the GAP (1/5e de ref)
C37: Voies / Wheel track | H37: Front : | I37: Rear :
C38: Voies / Wheel track | H38: 1584 | I38: 1574 | L38: Données issues du 1/5e de ref / Inputs from the GAP (1/5e de ref)
C39: Largeur / Body width | I39: 1846 | L39: Données issues du 1/5e de ref / Inputs from the GAP (1/5e de ref)
B41: Rang 1 / Row1 : | H41: X(mm) | I41: Y (mm) | J41: Z(mm)
C42: Point Hx Rang 1 / Hx Point row 1 | H42: 1334 | I42: -355 | J42: 390.3 | L42: Données issues du 1/5e de ref / Inputs from the GAP (1/5e de ref)
C43: Talon / Acc heel Point | J43: 90 | L43: Données issues du 1/5e de ref / Inputs from the GAP (1/5e de ref)
C44: Cote essieu pédale / Axle Pedal dist. | H44: 437 | L44: Données issues du 1/5e de ref / Inputs from the GAP (1/5e de ref)
C45: Point V1 / V1 point | H45: 946 | J45: 750 | L45: Données issues du 1/5e de ref / Inputs from the GAP (1/5e de ref)
...

Sheet INPUT2 - Veh Sub-Syst Mass
D2: PROGRAM : | E2: ='INPUT1 - Veh Geometry'!H8 -> STLA-S | H2: PROJECT : | I2: ='INPUT1 - Veh Geometry'!I8 -> J1X MHEV P2 FWD | L2: MODEL : | O2: ='INPUT1 - Veh Geometry'!J8 -> L2
B4: Evaluation AdP du MCI / CdG Evaluation at early stage | L4: Curb Mass | O4: X | P4: Y | Q4: Z (REF ground) | R4: Z (Curb ground) | S4: Z (GVW ground) | T4: Mfront | U4: Mrear
K5: Nb | L5: =SUMPRODUCT(L6:L252,K6:K252) -> 1456.289 | M5: Unsprung Coef | O5: =SUMPRODUCT(O6:O252,K6:K252,L6:L252)/$L$5 -> 998.48486 | P5: =SUMPRODUCT(P6:P252,K6:K252,L6:L252)/$L$5 -> -21.573203 | Q5: =SUMPRODUCT(Q6:Q252,$K6:$K252,$L6:$L252)/$L$5 -> 261.01732 | R5: =SUMPRODUCT(R6:R252,$K6:$K252,$L6:$L252)/$L$5 -> 256.80369 | S5: =SUMPRODUCT(S6:S252,$K6:$K252,$L6:$L252)/$L$5 -> 262.96106 | T5: =SUMIF($K6:$K252,">0",T6:T252) -> 882.05612 | U5: =SUMIF($K6:$K252,">0",U6:U252) -> 574.23288 | V5: =T5/L5 -> 0.60568755 | Z5: Perimeter | AA5: Module | AB5: A2MAC1 Level1 | AC5: A2MAC1 Level2 | AD5: A2MAC1 Level3 | AE5: A2MAC1 Structure | AF5: Découpages DEC5 | AJ5: commentaire | AN5: comment
B6: ADAPTATION | F6: POWERTRAIN ADAPTATION | L6: =SUMPRODUCT($K7:$K30,$L7:$L30) -> 124.6 | O6: =SUMPRODUCT($K7:$K30,$L7:$L30,O7:O30)/$L6 -> 923.00462 | P6: =SUMPRODUCT($K7:$K30,$L7:$L30,P7:P30)/$L6 -> -60.187961 | Q6: =SUMPRODUCT($K7:$K30,$L7:$L30,Q7:Q30)/$L6 -> 80.768186 | R6: =SUMPRODUCT($K7:$K30,$L7:$L30,R7:R30)/$L6 -> 80.768186 | S6: =SUMPRODUCT($K7:$K30,$L7:$L30,S7:S30)/$L6 -> 80.768186 | T6: =SUM(T7:T30) -> 79.031108 | U6: =SUMIF($K7:$K30,">0",$U7:$U30) -> 45.568892 | Y6: =IF(ISNUMBER(K6),L6*K6,0) -> 0 | Z6: CMAG | AB6: =IF(B6<>0,B6,AB5) -> ADAPTATION | AD6: =IF(D6<>"",D6,"") | AE6: =CONCATENATE(AB6," / ",AC6," / ",AD6) -> ADAPTATION / /
C7: ADDBLUE (+ reservoir) | F7: Addblue tank + liquid | O7: ='INPUT1 - Veh Geometry'!$H$106 -> 1944 | P7: ='INPUT1 - Veh Geometry'!$I$106 -> 42 | Q7: ='INPUT1 - Veh Geometry'!$J$106 -> 33 | R7: =$Q7 -> 33 | S7: =$Q7 -> 33 | T7: =L7*K7-U7 -> 0 | U7: =IF(ISNUMBER(K7),L7*K7*(O7-$D$262)/E,) -> 0 | Y7: =IF(ISNUMBER(K7),L7*K7,0) -> 0 | Z7: CMAG | AB7: =IF(B7<>0,B7,AB6) -> ADAPTATION | AC7: =IF(C7<>0,C7,AC6) -> ADDBLUE (+ reservoir) | AD7: =IF(D7<>"",D7,"") | AE7: =CONCATENATE(AB7," / ",AC7," / ",AD7) -> ADAPTATION / ADDBLUE (+ reservoir) /
C8: CIRCUIT CARBURANT | Y8: =IF(ISNUMBER(K8),L8*K8,0) -> 0 | Z8: CMAG | AB8: =IF(B8<>0,B8,AB7) -> ADAPTATION | AC8: =IF(C8<>0,C8,AC7) -> CIRCUIT CARBURANT | AD8: =IF(D8<>"",D8,"") | AE8: =CONCATENATE(AB8," / ",AC8," / ",AD8) -> ADAPTATION / CIRCUIT CARBURANT /
C9: CIRCUIT AIR | F9: Air intake loop | Y9: =IF(ISNUMBER(K9),L9*K9,0) -> 0 | Z9: CMAG | AB9: =IF(B9<>0,B9,AB8) -> ADAPTATION | AC9: =IF(C9<>0,C9,AC8) -> CIRCUIT AIR | AD9: =IF(D9<>"",D9,"") | AE9: =CONCATENATE(AB9," / ",AC9," / ",AD9) -> ADAPTATION / CIRCUIT AIR /
D10: Filtre | G10: Air filter | O10: ='INPUT1 - Veh Geometry'!H$87 -> -241.5 | P10: ='INPUT1 - Veh Geometry'!I$87 -> -48 | Q10: ='INPUT1 - Veh Geometry'!J$87 -> 144.4 | R10: =$Q10 -> 144.4 | S10: =$Q10 -> 144.4 | T10: =L10*K10-U10 -> 0 | U10: =IF(ISNUMBER(K10),L10*K10*(O10-$D$262)/E,) -> 0 | Y10: =IF(ISNUMBER(K10),L10*K10,0) -> 0 | Z10: CMAG | AA10: ACT02 | AB10: =IF(B10<>0,B10,AB9) -> ADAPTATION | AC10: =IF(C10<>0,C10,AC9) -> CIRCUIT AIR | AD10: =IF(D10<>"",D10,"") -> Filtre | AE10: =CONCATENATE(AB10," / ",AC10," / ",AD10) -> ADAPTATION / CIRCUIT AIR / Filtre | AH10: Sauf pour moteur EP6 (déjà compté dans le bilan moteur) | AL10: Except for EP6 (already counted in the mass of GMP)
D11: Durites | G11: Air pipes | K11: 1 | L11: 6.8 | O11: ='INPUT1 - Veh Geometry'!H$87 -> -241.5 | P11: ='INPUT1 - Veh Geometry'!I$87 -> -48 | Q11: ='INPUT1 - Veh Geometry'!J$87 -> 144.4 | R11: =$Q11 -> 144.4 | S11: =$Q11 -> 144.4 | T11: =L11*K11-U11 -> 7.3125758 | U11: =IF(ISNUMBER(K11),L11*K11*(O11-$D$262)/E,) -> -0.51257576 | Y11: =IF(ISNUMBER(K11),L11*K11,0) -> 6.8 | Z11: CMAG | AA11: ACT02 | AB11: =IF(B11<>0,B11,AB10) -> ADAPTATION | AC11: =IF(C11<>0,C11,AC10) -> CIRCUIT AIR | AD11: =IF(D11<>"",D11,"") -> Durites | AE11: =CONCATENATE(AB11," / ",AC11," / ",AD11) -> ADAPTATION / CIRCUIT AIR / Durites
D12: RAS | G12: CAC | O12: ='INPUT1 - Veh Geometry'!$H$115 -> -634.6 | P12: ='INPUT1 - Veh Geometry'!$I$115 -> -188 | Q12: ='INPUT1 - Veh Geometry'!$J$115 -> 191 | R12: =$Q12 -> 191 | S12: =$Q12 -> 191 | T12: =L12*K12-U12 -> 0 | U12: =IF(ISNUMBER(K12),L12*K12*(O12-$D$262)/E,) -> 0 | Y12: =IF(ISNUMBER(K12),L12*K12,0) -> 0 | Z12: CMAG | AA12: ACT01 | AB12: =IF(B12<>0,B12,AB11) -> ADAPTATION | AC12: =IF(C12<>0,C12,AC11) -> CIRCUIT AIR | AD12: =IF(D12<>"",D12,"") -> RAS | AE12: =CONCATENATE(AB12," / ",AC12," / ",AD12) -> ADAPTATION / CIRCUIT AIR / RAS | AH12: En cas de RAS déporté (type IRIS), mettre à jour la valeur du Y CDG | AL12: In case of a CAC in the wheel arch (IRIS Type), adjust the Y position
C13: CIRCUIT EAU | F13: Water cooling loop | Y13: =IF(ISNUMBER(K13),L13*K13,0) -> 0 | Z13: CMAG | AB13: =IF(B13<>0,B13,AB12) -> ADAPTATION | AC13: =IF(C13<>0,C13,AC12) -> CIRCUIT EAU | AD13: =IF(D13<>"",D13,"") | AE13: =CONCATENATE(AB13," / ",AC13," / ",AD13) -> ADAPTATION / CIRCUIT EAU /
D14: Système radiateur | G14: Radiator | O14: ='INPUT1 - Veh Geometry'!$H$115 -> -634.6 | P14: ='INPUT1 - Veh Geometry'!$I$115 -> -188 | Q14: ='INPUT1 - Veh Geometry'!$J$115 -> 191 | R14: =$Q14 -> 191 | S14: =$Q14 -> 191 | T14: =L14*K14-U14 -> 0 | U14: =IF(ISNUMBER(K14),L14*K14*(O14-$D$262)/E,) -> 0 | Y14: =IF(ISNUMBER(K14),L14*K14,0) -> 0 | Z14: CMAG | AA14: ACT01 | AB14: =IF(B14<>0,B14,AB13) -> ADAPTATION | AC14: =IF(C14<>0,C14,AC13) -> CIRCUIT EAU | AD14: =IF(D14<>"",D14,"") -> Système radiateur | AE14: =CONCATENATE(AB14," / ",AC14," / ",AD14) -> ADAPTATION / CIRCUIT EAU / Système radiateur | AH14: Valeurs entre 3 et 4kg suivant la taille et la classe de radia | AL14: Value between 3 and 4kg depending on size or class of radiator
D15: Durites | G15: Water pipes | O15: =('INPUT1 - Veh Geometry'!$H$116+'INPUT1 - Veh Geometry'!$H$93+'INPUT1 - Veh Geometry'!$H$87+'INPUT1 - Veh Geometry'!$H$90+'INPUT1 - Veh Geometry'!$H$98)/5 -> 105.18 | P15: =('INPUT1 - Veh Geometry'!$I$116+'INPUT1 - Veh Geometry'!$I$93+'INPUT1 - Veh Geometry'!$I$87+'INPUT1 - Veh Geometry'!$I$90+'INPUT1 - Veh Geometry'!$I$98)/5 -> 70.4 | Q15: =('INPUT1 - Veh Geometry'!$J$116+'INPUT1 - Veh Geometry'!$J$93+'INPUT1 - Veh Geometry'!$J$87+'INPUT1 - Veh Geometry'!$J$90+'INPUT1 - Veh Geometry'!$J$98)/5 -> 158.18 | R15: =$Q15 -> 158.18 | S15: =$Q15 -> 158.18 | T15: =L15*K15-U15 -> 0 | U15: =IF(ISNUMBER(K15),L15*K15*(O15-$D$262)/E,) -> 0 | Y15: =IF(ISNUMBER(K15),L15*K15,0) -> 0 | Z15: CMAG | AA15: ACT01 | AB15: =IF(B15<>0,B15,AB14) -> ADAPTATION | AC15: =IF(C15<>0,C15,AC14) -> CIRCUIT EAU | AD15: =IF(D15<>"",D15,"") -> Durites | AE15: =CONCATENATE(AB15," / ",AC15," / ",AD15) -> ADAPTATION / CIRCUIT EAU / Durites | AH15: Valeurs entre 4kg (tuyaux + boite dégazage) et 12kg (PHEV/BEV 4x4) | AL15: Value between 4kg (classic ICE) and 12kg (BEV/PHEV 4x4)
D16: Liquide de refroidissement | G16: Cooling liquid | K16: 1 | L16: 20.7 | O16: =('INPUT1 - Veh Geometry'!$H$116+'INPUT1 - Veh Geometry'!$H$93+'INPUT1 - Veh Geometry'!$H$87+'INPUT1 - Veh Geometry'!$H$90+'INPUT1 - Veh Geometry'!$H$98)/5 -> 105.18 | P16: =('INPUT1 - Veh Geometry'!$I$116+'INPUT1 - Veh Geometry'!$I$93+'INPUT1 - Veh Geometry'!$I$87+'INPUT1 - Veh Geometry'!$I$90+'INPUT1 - Veh Geometry'!$I$98)/5 -> 70.4 | Q16: =('INPUT1 - Veh Geometry'!$J$116+'INPUT1 - Veh Geometry'!$J$93+'INPUT1 - Veh Geometry'!$J$87+'INPUT1 - Veh Geometry'!$J$90+'INPUT1 - Veh Geometry'!$J$98)/5 -> 158.18 | R16: =$Q16 -> 158.18 | S16: =$Q16 -> 158.18 | T16: =L16*K16-U16 -> 19.542055 | U16: =IF(ISNUMBER(K16),L16*K16*(O16-$D$262)/E,) -> 1.1579455 | Y16: =IF(ISNUMBER(K16),L16*K16,0) -> 20.7 | Z16: CMAG | AA16: ACT03 | AB16: =IF(B16<>0,B16,AB15) -> ADAPTATION | AC16: =IF(C16<>0,C16,AC15) -> CIRCUIT EAU | AD16: =IF(D16<>"",D16,"") -> Liquide de refroidissement | AE16: =CONCATENATE(AB16," / ",AC16," / ",AD16) -> ADAPTATION / CIRCUIT EAU / Liquide de refroidissement | AH16: Valeurs entre 5kg (ICE) et 15kg (BEV) | AL16: value between 5kg (ICE) and 15kg (PHEV/BEV 4x4)
D17: Système motoventilateur | G17: Fan system | O17: ='INPUT1 - Veh Geometry'!$H$115+100 -> -534.6 | P17: ='INPUT1 - Veh Geometry'!$I$115 -> -188 | Q17: ='INPUT1 - Veh Geometry'!$J$115 -> 191 | R17: =$Q17 -> 191 | S17: =$Q17 -> 191 | T17: =L17*K17-U17 -> 0 | U17: =IF(ISNUMBER(K17),L17*K17*(O17-$D$262)/E,) -> 0 | Y17: =IF(ISNUMBER(K17),L17*K17,0) -> 0 | Z17: CMAG | AA17: ACT01 | AB17: =IF(B17<>0,B17,AB16) -> ADAPTATION | AC17: =IF(C17<>0,C17,AC16) -> CIRCUIT EAU | AD17: =IF(D17<>"",D17,"") -> Système motoventilateur | AE17: =CONCATENATE(AB17," / ",AC17," / ",AD17) -> ADAPTATION / CIRCUIT EAU / Système motoventilateur | AH17: Prendre l'ensemble ventilateur + cadre, entre 3 et 4kg en général | AL17: value of entire module with air dam, usually from 3 to 4kg
D18: Système pompe auxiliaire | G18: Auxiliary water pumps | O18: ='INPUT1 - Veh Geometry'!$H$87 -> -241.5 | P18: ='INPUT1 - Veh Geometry'!$I$87 -> -48 | Q18: ='INPUT1 - Veh Geometry'!$J$87-100 -> 44.4 | R18: =$Q18 -> 44.4 | S18: =$Q18 -> 44.4 | T18: =L18*K18-U18 -> 0 | U18: =IF(ISNUMBER(K18),L18*K18*(O18-$D$262)/E,) -> 0 | Y18: =IF(ISNUMBER(K18),L18*K18,0) -> 0 | Z18: DSEE | AB18: =IF(B18<>0,B18,AB17) -> ADAPTATION | AC18: =IF(C18<>0,C18,AC17) -> CIRCUIT EAU | AD18: =IF(D18<>"",D18,"") -> Système pompe auxiliaire | AE18: =CONCATENATE(AB18," / ",AC18," / ",AD18) -> ADAPTATION / CIRCUIT EAU / Système pompe auxiliaire | AH18: en général, 1 pompe pour ICE, 2 ou 3 pompes pour les BEV/ MHEV / BEV; 0,3 à 0,6kg pour chaque pompe | AL18: 1 pump fpr ICE, 2 to 3 pumps for MHEV / BEV / PHEV; value of 0,3 to 0,6kg each
C19: COMMANDE VITESSE | F19: Gear shift command | K19: 1 | L19: 1.3 | O19: ='INPUT1 - Veh Geometry'!$H$42-300 -> 1034 | P19: ='INPUT1 - Veh Geometry'!$I$42 -> -355 | Q19: ='INPUT1 - Veh Geometry'!$J$42-100 -> 290.3 | R19: =$Q19 -> 290.3 | S19: =$Q19 -> 290.3 | T19: =L19*K19-U19 -> 0.7699053 | U19: =IF(ISNUMBER(K19),L19*K19*(O19-$D$262)/E,) -> 0.5300947 | Y19: =IF(ISNUMBER(K19),L19*K19,0) -> 1.3 | Z19: CMAG | AA19: ACT11 | AB19: =IF(B19<>0,B19,AB18) -> ADAPTATION | AC19: =IF(C19<>0,C19,AC18) -> COMMANDE VITESSE | AD19: =IF(D19<>"",D19,"") | AE19: =CONCATENATE(AB19," / ",AC19," / ",AD19) -> ADAPTATION / COMMANDE VITESSE / | AH19: levier de vitesse | AL19: gear lever
C20: ECHAPPEMENT | F20: Exhaust line | K20: 1 | L20: 22.9 | O20: ='INPUT1 - Veh Geometry'!$H$101 -> 1265 | P20: ='INPUT1 - Veh Geometry'!$I$101 -> -290 | Q20: ='INPUT1 - Veh Geometry'!$J$101 -> -32 | R20: =$Q20 -> -32 | S20: =$Q20 -> -32 | T20: =L20*K20-U20 -> 11.558428 | U20: =IF(ISNUMBER(K20),L20*K20*(O20-$D$262)/E,) -> 11.341572 | Y20: =IF(ISNUMBER(K20),L20*K20,0) -> 22.9 | Z20: CMAG | AA20: ACT08+09 | AB20: =IF(B20<>0,B20,AB19) -> ADAPTATION | AC20: =IF(C20<>0,C20,AC19) -> ECHAPPEMENT | AD20: =IF(D20<>"",D20,"") | AE20: =CONCATENATE(AB20," / ",AC20," / ",AD20) -> ADAPTATION / ECHAPPEMENT / | AH20: ligne complète: catalyseur et ligne froide | AL20: full exhasut line with catalyser and cold line
C21: ECRANS THERMIQUE | F21: Thermal shields | L21: 0 | O21: ='INPUT1 - Veh Geometry'!$H$101 -> 1265 | P21: ='INPUT1 - Veh Geometry'!$I$101 -> -290 | Q21: ='INPUT1 - Veh Geometry'!$J$101 -> -32 | R21: =$Q21 -> -32 | S21: =$Q21 -> -32 | T21: =L21*K21-U21 -> 0 | U21: =IF(ISNUMBER(K21),L21*K21*(O21-$D$262)/E,) -> 0 | Y21: =IF(ISNUMBER(K21),L21*K21,0) -> 0 | Z21: CMAG | AA21: Hors module | AB21: =IF(B21<>0,B21,AB20) -> ADAPTATION | AC21: =IF(C21<>0,C21,AC20) -> ECRANS THERMIQUE | AD21: =IF(D21<>"",D21,"") | AE21: =CONCATENATE(AB21," / ",AC21," / ",AD21) -> ADAPTATION / ECRANS THERMIQUE / | AH21: Entre 2 et 2,8kg | AL21: from 2 to 3kg
C22: FACADE | K22: 1 | L22: 13 | O22: ='INPUT1 - Veh Geometry'!$H$115 -> -634.6 | P22: ='INPUT1 - Veh Geometry'!$I$115 -> -188 | Q22: ='INPUT1 - Veh Geometry'!$J$115 -> 191 | R22: =$Q22 -> 191 | S22: =$Q22 -> 191 | T22: =L22*K22-U22 -> 15.915644 | U22: =IF(ISNUMBER(K22),L22*K22*(O22-$D$262)/E,) -> -2.9156439 | Y22: =IF(ISNUMBER(K22),L22*K22,0) -> 13 | Z22: ADTH | AB22: =IF(B22<>0,B22,AB21) -> ADAPTATION | AC22: =IF(C22<>0,C22,AC21) -> FACADE | AD22: =IF(D22<>"",D22,"") | AE22: =CONCATENATE(AB22," / ",AC22," / ",AD22) -> ADAPTATION / FACADE /
C23: LIQUIDE ADDITIF | L23: 0 | O23: ='INPUT1 - Veh Geometry'!$H$101 -> 1265 | P23: ='INPUT1 - Veh Geometry'!$I$101 -> -290 | Q23: ='INPUT1 - Veh Geometry'!$J$101 -> -32 | R23: =$Q23 -> -32 | S23: =$Q23 -> -32 | T23: =L23*K23-U23 -> 0 | U23: =IF(ISNUMBER(K23),L23*K23*(O23-$D$262)/E,) -> 0 | Y23: =IF(ISNUMBER(K23),L23*K23,0) -> 0 | Z23: CMAG | AB23: =IF(B23<>0,B23,AB22) -> ADAPTATION | AC23: =IF(C23<>0,C23,#REF!) -> LIQUIDE ADDITIF | AD23: =IF(D23<>"",D23,"") | AE23: =CONCATENATE(AB23," / ",AC23," / ",AD23) -> ADAPTATION / LIQUIDE ADDITIF /
B24: Déjà en ligne 16 | C24: LIQUIDE REFROIDISSEMENT | G24: Cooling liquid | O24: =('INPUT1 - Veh Geometry'!$H$116+'INPUT1 - Veh Geometry'!$H$93+'INPUT1 - Veh Geometry'!$H$87+'INPUT1 - Veh Geometry'!$H$90+'INPUT1 - Veh Geometry'!$H$98)/5 -> 105.18 | P24: =('INPUT1 - Veh Geometry'!$I$116+'INPUT1 - Veh Geometry'!$I$93+'INPUT1 - Veh Geometry'!$I$87+'INPUT1 - Veh Geometry'!$I$90+'INPUT1 - Veh Geometry'!$I$98)/5 -> 70.4 | Q24: =('INPUT1 - Veh Geometry'!$J$116+'INPUT1 - Veh Geometry'!$J$93+'INPUT1 - Veh Geometry'!$J$87+'INPUT1 - Veh Geometry'!$J$90+'INPUT1 - Veh Geometry'!$J$98)/5 -> 158.18 | R24: =$Q24 -> 158.18 | S24: =$Q24 -> 158.18 | T24: =L24*K24-U24 -> 0 | U24: =IF(ISNUMBER(K24),L24*K24*(O24-$D$262)/E,) -> 0 | Y24: =IF(ISNUMBER(K24),L24*K24,0) -> 0 | Z24: CMAG | AA24: ACT03 | AB24: =IF(B24<>0,B24,AB23) -> Déjà en ligne 16 | AC24: =IF(C24<>0,C24,AC23) -> LIQUIDE REFROIDISSEMENT | AD24: =IF(D24<>"",D24,"") | AE24: =CONCATENATE(AB24," / ",AC24," / ",AD24) -> Déjà en ligne 16 / LIQUIDE REFROIDISSEMENT / | AH24: Valeurs entre 5kg (ICE) et 15kg (BEV) | AL24: value between 5kg (ICE) and 15kg (PHEV/BEV 4x4)
C25: PEDALIER | F25: Pedals | K25: 1 | L25: 2.2 | O25: ='INPUT1 - Veh Geometry'!$H$104 -> 305 | P25: ='INPUT1 - Veh Geometry'!$I$104 -> -201 | Q25: ='INPUT1 - Veh Geometry'!$J$104 -> 316 | R25: =$Q25 -> 316 | S25: =$Q25 -> 316 | T25: =L25*K25-U25 -> 1.9104167 | U25: =IF(ISNUMBER(K25),L25*K25*(O25-$D$262)/E,) -> 0.28958333 | Y25: =IF(ISNUMBER(K25),L25*K25,0) -> 2.2 | Z25: CMAG | AA25: ACT07 | AB25: =IF(B25<>0,B25,AB24) -> Déjà en ligne 16 | AC25: =IF(C25<>0,C25,AC24) -> PEDALIER | AD25: =IF(D25<>"",D25,"") | AE25: =CONCATENATE(AB25," / ",AC25," / ",AD25) -> Déjà en ligne 16 / PEDALIER / | AH25: Valeur moyenne, 1,5 à 2kg | AL25: mean value from 1,5 to 2kg
C26: RESERVOIR CARBURANT | F26: Fuel tank | K26: 1 | L26: 48 | O26: ='INPUT1 - Veh Geometry'!$H$56 -> 1960 | P26: ='INPUT1 - Veh Geometry'!$I$56 -> 38 | Q26: ='INPUT1 - Veh Geometry'!$J$56 -> 33 | R26: =$Q26 -> 33 | S26: =$Q26 -> 33 | T26: =L26*K26-U26 -> 11.590909 | U26: =IF(ISNUMBER(K26),L26*K26*(O26-$D$262)/E,) -> 36.409091 | Y26: =IF(ISNUMBER(K26),L26*K26,0) -> 48 | Z26: CMAG | AA26: ACT06 | AB26: =IF(B26<>0,B26,AB25) -> Déjà en ligne 16 | AC26: =IF(C26<>0,C26,AC25) -> RESERVOIR CARBURANT | AD26: =IF(D26<>"",D26,"") | AE26: =CONCATENATE(AB26," / ",AC26," / ",AD26) -> Déjà en ligne 16 / RESERVOIR CARBURANT / | AH26: Entre 9kg (réservoir simple 45L) et 15kg (réservoir pressurisé 60L) | AL26: From 9kg (simple tank, 45L) to 16kg (pressurised tank, 60L)
C27: Canister | F27: Canister | L27: 0 | O27: ='INPUT1 - Veh Geometry'!$H$56 -> 1960 | P27: ='INPUT1 - Veh Geometry'!$I$56 -> 38 | Q27: ='INPUT1 - Veh Geometry'!$J$56 -> 33 | R27: =$Q27 -> 33 | S27: =$Q27 -> 33 | T27: =L27*K27-U27 -> 0 | U27: =IF(ISNUMBER(K27),L27*K27*(O27-$D$262)/E,) -> 0 | Y27: =IF(ISNUMBER(K27),L27*K27,0) -> 0 | Z27: CMAG | AA27: ACT06 | AB27: =IF(B27<>0,B27,AB26) -> Déjà en ligne 16 | AC27: =IF(C27<>0,C27,AC26) -> Canister | AD27: =IF(D27<>"",D27,"") | AE27: =CONCATENATE(AB27," / ",AC27," / ",AD27) -> Déjà en ligne 16 / Canister / | AH27: Entre 0,5kg (€6 Europe) et 3kg (dépol €7 et Chine) | AL27: From 0,5kg (€6) to 3kg (€7 and China)
C28: Masse carburant | F28: Fuel mass | L28: 0 | O28: ='INPUT1 - Veh Geometry'!$H$56 -> 1960 | P28: ='INPUT1 - Veh Geometry'!I56 -> 38 | Q28: ='INPUT1 - Veh Geometry'!$J$56 -> 33 | R28: =$Q28 -> 33 | S28: =$Q28 -> 33 | T28: =L28*K28-U28 -> 0 | U28: =IF(ISNUMBER(K28),L28*K28*(O28-$D$262)/E,) -> 0 | Y28: =IF(ISNUMBER(K28),L28*K28,0) -> 0 | Z28: CMAG | AA28: ACT06 | AB28: =IF(B28<>0,B28,AB27) -> Déjà en ligne 16 | AC28: =IF(C28<>0,C28,AC27) -> Masse carburant | AD28: =IF(D28<>"",D28,"") | AE28: =CONCATENATE(AB28," / ",AC28," / ",AD28) -> Déjà en ligne 16 / Masse carburant / | AH28: Faire le calcul nbre de litres x0,75 (essence) ou 0,8 (diesel) | AL28: Liters * 0,75 (gasoline) or 0,8 (diesel)
C29: SUPPORT GMP AV | F29: Front Electric engine brackets | K29: 1 | L29: 9.7 | O29: ='INPUT1 - Veh Geometry'!H87 -> -241.5 | P29: ='INPUT1 - Veh Geometry'!I87 -> -48 | Q29: ='INPUT1 - Veh Geometry'!J87 -> 144.4 | R29: =$Q29 -> 144.4 | S29: =$Q29 -> 144.4 | T29: =L29*K29-U29 -> 10.431174 | U29: =IF(ISNUMBER(K29),L29*K29*(O29-$D$262)/E,) -> -0.73117424 | Y29: =IF(ISNUMBER(K29),L29*K29,0) -> 9.7 | Z29: CMAG | AA29: ACT12 | AB29: =IF(B29<>0,B29,AB28) -> Déjà en ligne 16 | AC29: =IF(C29<>0,C29,AC28) -> SUPPORT GMP AV | AD29: =IF(D29<>"",D29,"") | AE29: =CONCATENATE(AB29," / ",AC29," / ",AD29) -> Déjà en ligne 16 / SUPPORT GMP AV /
C30: Supports MEL AR | F30: Rear Electric engine brackets | O30: ='INPUT1 - Veh Geometry'!H90 -> 0 | P30: ='INPUT1 - Veh Geometry'!I90 -> 0 | Q30: ='INPUT1 - Veh Geometry'!J90 -> 0 | R30: =$Q30 -> 0 | S30: =$Q30 -> 0 | T30: =L30*K30-U30 -> 0 | U30: =IF(ISNUMBER(K30),L30*K30*(O30-$D$262)/E,) -> 0 | Y30: =IF(ISNUMBER(K30),L30*K30,0) -> 0 | Z30: CMAG | AA30: ACT12 | AB30: =IF(B30<>0,B30,AB29) -> Déjà en ligne 16 | AC30: =IF(C30<>0,C30,AC29) -> Supports MEL AR | AD30: =IF(D30<>"",D30,"") | AE30: =CONCATENATE(AB30," / ",AC30," / ",AD30) -> Déjà en ligne 16 / Supports MEL AR / | AH30: Pour PHEV/BEV 4x4 | AL30: For PHEV / BEV 4x4
B31: ADTH | F31: ADTH | L31: =SUMPRODUCT(K32:K37,L32:L37) -> 17.4 | O31: =SUMPRODUCT($K32:$K37,$L32:$L37,O32:O37)/$L31 -> -37.214751 | P31: =SUMPRODUCT($K32:$K37,$L32:$L37,P32:P37)/$L31 -> -22.791188 | Q31: =SUMPRODUCT($K32:$K37,$L32:$L37,Q32:Q37)/$L31 -> 243.23218 | R31: =SUMPRODUCT($K32:$K37,$L32:$L37,R32:R37)/$L31 -> 243.23218 | S31: =SUMPRODUCT($K32:$K37,$L32:$L37,S32:S37)/$L31 -> 243.23218 | T31: =SUM(T32:T37) -> 17.365165 | U31: =SUMIF($K32:$K37,">0",$U32:$U37) -> 0.034834596 | Y31: =IF(ISNUMBER(K31),L31*K31,0) -> 0 | Z31: ADTH | AB31: =IF(B31<>0,B31,AB30) -> ADTH | AC31: =IF(C31<>0,C31,AC30) -> Supports MEL AR | AD31: =IF(D31<>"",D31,"") | AE31: =CONCATENATE(AB31," / ",AC31," / ",AD31) -> ADTH / Supports MEL AR /
C32: Gaz de climatisation | F32: Air conditioning gas | O32: ='INPUT1 - Veh Geometry'!$H$115 -> -634.6 | P32: ='INPUT1 - Veh Geometry'!$I$115 -> -188 | Q32: ='INPUT1 - Veh Geometry'!$J$115 -> 191 | R32: =$Q32 -> 191 | S32: =$Q32 -> 191 | T32: =L32*K32-U32 -> 0 | U32: =IF(ISNUMBER(K32),L32*K32*(O32-$D$262)/E,) -> 0 | Y32: =IF(ISNUMBER(K32),L32*K32,0) -> 0 | Z32: ADTH | AB32: =IF(B32<>0,B32,AB31) -> ADTH | AC32: =IF(C32<>0,C32,AC31) -> Gaz de climatisation | AD32: =IF(D32<>"",D32,"") | AE32: =CONCATENATE(AB32," / ",AC32," / ",AD32) -> ADTH / Gaz de climatisation / | AH32: valeur usuelle, entre 0,8 et 1kg | AL32: mean value from 0,8 to 1kg
C33: Conduits de clim | F33: Air conditioning ducts | K33: 1 | L33: 2.8 | O33: =('INPUT1 - Veh Geometry'!$H$115*2+'INPUT1 - Veh Geometry'!$H$102)/3 -> -334.06667 | P33: =('INPUT1 - Veh Geometry'!$I$115*2+'INPUT1 - Veh Geometry'!$I$102)/3 -> -113.66667 | Q33: =('INPUT1 - Veh Geometry'!$J$115*2+'INPUT1 - Veh Geometry'!$J$102)/3 -> 240 | R33: =$Q33 -> 240 | S33: =$Q33 -> 240 | T33: =L33*K33-U33 -> 3.1092374 | U33: =IF(ISNUMBER(K33),L33*K33*(O33-$D$262)/E,) -> -0.30923737 | Y33: =IF(ISNUMBER(K33),L33*K33,0) -> 2.8 | Z33: ADTH | AB33: =IF(B33<>0,B33,AB32) -> ADTH | AC33: =IF(C33<>0,C33,AC32) -> Conduits de clim | AD33: =IF(D33<>"",D33,"") | AE33: =CONCATENATE(AB33," / ",AC33," / ",AD33) -> ADTH / Conduits de clim / | AH33: valeur mpyenne, 2kg | AL33: mean value, 2kg
C34: Groupe de clim | F34: HVAC | K34: 1 | L34: 7.5 | O34: ='INPUT1 - Veh Geometry'!$H$102 -> 267 | P34: ='INPUT1 - Veh Geometry'!$I$102 -> 35 | Q34: ='INPUT1 - Veh Geometry'!$J$102 -> 338 | R34: =$Q34 -> 338 | S34: =$Q34 -> 338 | T34: =L34*K34-U34 -> 6.6207386 | U34: =IF(ISNUMBER(K34),L34*K34*(O34-$D$262)/E,) -> 0.87926136 | Y34: =IF(ISNUMBER(K34),L34*K34,0) -> 7.5 | Z34: ADTH | AB34: =IF(B34<>0,B34,AB33) -> ADTH | AC34: =IF(C34<>0,C34,AC33) -> Groupe de clim | AD34: =IF(D34<>"",D34,"") | AE34: =CONCATENATE(AB34," / ",AC34," / ",AD34) -> ADTH / Groupe de clim / | AH34: valeur entre 8 et 10kg | AL34: mean value from 8 to 10kg
C35: Compresseur de clim + support | F35: Compressor + bracket | K35: 1 | L35: 7.1 | O35: ='INPUT1 - Veh Geometry'!H87 -> -241.5 | P35: ='INPUT1 - Veh Geometry'!I87 -> -48 | Q35: ='INPUT1 - Veh Geometry'!$J$87 -> 144.4 | R35: =$Q35 -> 144.4 | S35: =$Q35 -> 144.4 | T35: =L35*K35-U35 -> 7.6351894 | U35: =IF(ISNUMBER(K35),L35*K35*(O35-$D$262)/E,) -> -0.53518939 | Y35: =IF(ISNUMBER(K35),L35*K35,0) -> 7.1 | Z35: ADTH | AB35: =IF(B35<>0,B35,AB34) -> ADTH | AC35: =IF(C35<>0,C35,AC34) -> Compresseur de clim + support | AD35: =IF(D35<>"",D35,"") | AE35: =CONCATENATE(AB35," / ",AC35," / ",AD35) -> ADTH / Compresseur de clim + support / | AH35: valeur entre 4 et 6kg | AL35: mean value from 4 to 6kg
C36: Chiller + support | F36: Chiller + bracket | O36: ='INPUT1 - Veh Geometry'!$H$115 -> -634.6 | P36: ='INPUT1 - Veh Geometry'!$I$115 -> -188 | Q36: ='INPUT1 - Veh Geometry'!$J$115 -> 191 | R36: =$Q36 -> 191 | S36: =$Q36 -> 191 | T36: =L36*K36-U36 -> 0 | U36: =IF(ISNUMBER(K36),L36*K36*(O36-$D$262)/E,) -> 0 | Y36: =IF(ISNUMBER(K36),L36*K36,0) -> 0 | Z36: ADTH | AB36: =IF(B36<>0,B36,AB35) -> ADTH | AC36: =IF(C36<>0,C36,AC35) -> Chiller + support | AD36: =IF(D36<>"",D36,"") | AE36: =CONCATENATE(AB36," / ",AC36," / ",AD36) -> ADTH / Chiller + support / | AH36: chiller, entre 0,5 et 1kg | AL36: mean value for the chiller, from 0,5 to 1kg
C37: CTP (Water heater) + support | F37: CTP (Water heater) + bracket | O37: ='INPUT1 - Veh Geometry'!$H$46 -> 475.2 | P37: ='INPUT1 - Veh Geometry'!$I$46 -> 0 | Q37: ='INPUT1 - Veh Geometry'!$J$46 -> 531.8 | R37: =$Q37 -> 531.8 | S37: =$Q37 -> 531.8 | T37: =L37*K37-U37 -> 0 | U37: =IF(ISNUMBER(K37),L37*K37*(O37-$D$262)/E,) -> 0 | Y37: =IF(ISNUMBER(K37),L37*K37,0) -> 0 | Z37: ADTH | AB37: =IF(B37<>0,B37,AB36) -> ADTH | AC37: =IF(C37<>0,C37,AC36) -> CTP (Water heater) + support | AD37: =IF(D37<>"",D37,"") | AE37: =CONCATENATE(AB37," / ",AC37," / ",AD37) -> ADTH / CTP (Water heater) + support / | AH37: valeur entre 1,5 et 2,5k pour la CTP, ajouter la meme masse pour le support | AL37: mean value from 1,5 to 2,5kg for the WH, add the same mass for its bracket
B38: AILES | F38: Wings | L38: =SUMPRODUCT(K39:K40,L39:L40) -> 4.4 | O38: =SUMPRODUCT($K39:$K40,$L39:$L40,O39:O40)/$L38 -> 72.5 | P38: =SUMPRODUCT($K39:$K40,$L39:$L40,P39:P40)/$L38 -> 0 | Q38: =SUMPRODUCT($K39:$K40,$L39:$L40,Q39:Q40)/$L38 -> 523.9 | R38: =SUMPRODUCT($K39:$K40,$L39:$L40,R39:R40)/$L38 -> 523.9 | S38: =SUMPRODUCT($K39:$K40,$L39:$L40,S39:S40)/$L38 -> 523.9 | T38: =SUM(T39:T40) -> 4.2083333 | U38: =SUMIF($K39:$K40,">0",$U39:$U40) -> 0.19166667 | Y38: =IF(ISNUMBER(K38),L38*K38,0) -> 0 | Z38: SOEE | AB38: =IF(B38<>0,B38,AB37) -> AILES | AC38: =IF(C38<>0,C38,AC37) -> CTP (Water heater) + support | AD38: =IF(D38<>"",D38,"") | AE38: =CONCATENATE(AB38," / ",AC38," / ",AD38) -> AILES / CTP (Water heater) + support /
C39: Ailes avant | F39: Front wing | K39: 1 | L39: 4.4 | O39: ='INPUT1 - Veh Geometry'!$H$61+115 -> 72.5 | P39: 0 | Q39: ='INPUT1 - Veh Geometry'!$J$61+'INPUT1 - Veh Geometry'!$H$81/2+100 -> 523.9 | R39: =$Q39 -> 523.9 | S39: =$Q39 -> 523.9 | T39: =L39*K39-U39 -> 4.2083333 | U39: =IF(ISNUMBER(K39),L39*K39*(O39-$D$262)/E,) -> 0.19166667 | Y39: =IF(ISNUMBER(K39),L39*K39,0) -> 4.4 | Z39: SOEE | AB39: =IF(B39<>0,B39,AB38) -> AILES | AC39: =IF(C39<>0,C39,AC38) -> Ailes avant | AD39: =IF(D39<>"",D39,"") | AE39: =CONCATENATE(AB39," / ",AC39," / ",AD39) -> AILES / Ailes avant / | AH39: valeur usuelle autours de 4kg | AL39: mean value around 4kg
C40: Ailes arrière | F40: Rear wing | O40: ='INPUT1 - Veh Geometry'!$H$33+'INPUT1 - Veh Geometry'!$H$61+300 -> 2897.5 | P40: 0 | Q40: ='INPUT1 - Veh Geometry'!$J$72+'INPUT1 - Veh Geometry'!$H$81 -> 789.8 | R40: =$Q40 -> 789.8 | S40: =$Q40 -> 789.8 | T40: =L40*K40-U40 -> 0 | U40: =IF(ISNUMBER(K40),L40*K40*(O40-$D$262)/E,) -> 0 | Y40: =IF(ISNUMBER(K40),L40*K40,0) -> 0 | Z40: SOEE | AB40: =IF(B40<>0,B40,AB39) -> AILES | AC40: =IF(C40<>0,C40,AC39) -> Ailes arrière | AD40: =IF(D40<>"",D40,"") | AE40: =CONCATENATE(AB40," / ",AC40," / ",AD40) -> AILES / Ailes arrière / | AH40: 0 en général, inclus dans coté de caisse | AL40: 0 in general, included in the side panel
B41: ASSISES | F41: Seats | L41: =SUMPRODUCT(L42:L46,K42:K46) -> 58.8 | O41: =SUMPRODUCT($K42:$K46,$L42:$L46,O42:O46)/$L41 -> 1676.4966 | P41: =SUMPRODUCT($K42:$K46,$L42:$L46,P42:P46)/$L41 -> 0 | Q41: =SUMPRODUCT($K42:$K46,$L42:$L46,Q42:Q46)/$L41 -> 486.55187 | R41: =SUMPRODUCT($K42:$K46,$L42:$L46,R42:R46)/$L41 -> 486.55187 | S41: =SUMPRODUCT($K42:$K46,$L42:$L46,S42:S46)/$L41 -> 486.55187 | T41: =SUM(T42:T46) -> #VALUE! | U41: =SUMIF($K42:$K46,">0",$U42:$U46) -> 38.286742 | Y41: =IF(ISNUMBER(K41),L41*K41,0) -> 0 | Z41: SPCS | AB41: =IF(B41<>0,B41,AB40) -> ASSISES | AC41: =IF(C41<>0,C41,AC40) -> Ailes arrière | AD41: =IF(D41<>"",D41,"") | AE41: =CONCATENATE(AB41," / ",AC41," / ",AD41) -> ASSISES / Ailes arrière /
C42: ASSISE AR RG2 | F42: Row 2 seats | K42: 1 | L42: 25.3 | O42: ='INPUT1 - Veh Geometry'!$H$49 -> 2130 | P42: 0 | Q42: ='INPUT1 - Veh Geometry'!$J$49+225 -> 614 | R42: =$Q42 -> 614 | S42: =$Q42 -> 614 | T42: =L42*K42-U42 -> 4.4802083 | U42: =IF(ISNUMBER(K42),L42*K42*(O42-$D$262)/E,) -> 20.819792 | Y42: =IF(ISNUMBER(K42),L42*K42,0) -> 25.3 | Z42: SPCS | AB42: =IF(B42<>0,B42,AB41) -> ASSISES | AC42: =IF(C42<>0,C42,AC41) -> ASSISE AR RG2 | AD42: =IF(D42<>"",D42,"") | AE42: =CONCATENATE(AB42," / ",AC42," / ",AD42) -> ASSISES / ASSISE AR RG2 / | AH42: Dépend du concept: banquette fixe/coulissante, siège amovible | AL42: very large variations, depending on the concept
...

Sheet UNSPRUNG Mass estimation
B2: UNSPRUNG MASS ESTIMATION | L2: COMPARISON WITH A REFERENCE VEHICLE
I4: Estimated with figures from sheet 'Evaluations mass+CoG' | M4: Copy here the unsprung mass of a refrence vehicle | O4: If delta between Estimation versus Reference < 3% : Green
O5: If delta between Estimation versus Reference > 3% : Red
C7: ='INPUT1 - Veh Geometry'!H8 -> STLA-S | D7: Plaque de conception
C8: ='INPUT1 - Veh Geometry'!I8 -> J1X MHEV P2 FWD | D8: Finition | I8: ='INPUT1 - Veh Geometry'!J8 -> L2
D9: Sièges
D10: Hybridation
D11: Pack technique
D12: Spécificité technique
D13: Charge utile
D14: Roues
D15: Pôle
D16: Moteur
D17: Boite
C18: Màj du :
C19: Précédente diffusion :
C20: LES MASSES CI-DESSOUS NE SONT PAS DES VALEURS HOMOLOGUEES. POUR CES DERNIERES CONTACTER LE SERVICE HOMOLOGATION
E21: MASSE A VIDE
E22: EQUIPEMENTS OPTIONNELS
E25: MOTEUR NU
E26: HABILLAGE MOTEUR
E27: BOITE DE VITESSE (avec couplage)
E28: ADAPTATION (avec fluides)
C30: DETAIL MASSES NON SUSPENDUES (MNS) | H30: components mass without coefficient | I30: MNS with coefficient applied : | O30: Delta (%) between Estimation and Refrence
C31: Masses non suspendues AV | E31: Coeff | I31: =SUM(I32:I47) -> 109.94 | M31: 160 | O31: =IF(ISBLANK(M31),"/",1/M31*(I31-M31)) -> -0.312875
C32: FRN | D32: TRANSMISSION AV | E32: C61 | F32: 0.7 | I32: =H32*F32 -> 0 | O32: =IF(ISBLANK(M32),"/",1/M32*(I32-M32)) -> /
C33: FRN | D33: TRANSMISSION A JOINTS AV | E33: C71 | F33: 0.7 | H33: ='INPUT2 - Veh Sub-Syst Mass'!L233*'INPUT2 - Veh Sub-Syst Mass'!K233+'INPUT2 - Veh Sub-Syst Mass'!L234*'INPUT2 - Veh Sub-Syst Mass'!K234 -> 11.6 | I33: =H33*F33 -> 8.12 | M33: 11 | O33: =IF(ISBLANK(M33),"/",1/M33*(I33-M33)) -> -0.26181818
C34: FRN | D34: ELEMENTS COMMUNS 1C7 | E34: C7Z | F34: 0.7 | I34: =H34*F34 -> 0 | O34: =IF(ISBLANK(M34),"/",1/M34*(I34-M34)) -> /
C35: FRN | D35: MOYEU – ROULEMENT ROUE AV | E35: E13 | F35: 1 | H35: ='INPUT2 - Veh Sub-Syst Mass'!L204*'INPUT2 - Veh Sub-Syst Mass'!K204 -> 5.7 | I35: =H35*F35 -> 5.7 | O35: =IF(ISBLANK(M35),"/",1/M35*(I35-M35)) -> /
C36: FRN | D36: ROUE PRINCIPALE | E36: E31 | F36: 0.5 | H36: ='INPUT2 - Veh Sub-Syst Mass'!K189*'INPUT2 - Veh Sub-Syst Mass'!L189+'INPUT2 - Veh Sub-Syst Mass'!K188*'INPUT2 - Veh Sub-Syst Mass'!L188 -> 88.6 | I36: =H36*F36 -> 44.3 | O36: =IF(ISBLANK(M36),"/",1/M36*(I36-M36)) -> /
C37: FRN | D37: ENJOLIVEUR ROUE | E37: E33 | F37: 0.5 | I37: =H37*F37 -> 0 | O37: =IF(ISBLANK(M37),"/",1/M37*(I37-M37)) -> /
C38: FRN | D38: INDICATEUR PERTE PRESSION | E38: E34 | F38: 0.5 | I38: =H38*F38 -> 0 | O38: =IF(ISBLANK(M38),"/",1/M38*(I38-M38)) -> /
C39: FRN | D39: DISQUE – TAMBOUR AV | E39: F11 | F39: 1 | H39: ='INPUT2 - Veh Sub-Syst Mass'!L157*'INPUT2 - Veh Sub-Syst Mass'!K157 -> 15.8 | I39: =H39*F39 -> 15.8 | O39: =IF(ISBLANK(M39),"/",1/M39*(I39-M39)) -> /
C40: FRN | D40: ETRIER – PLATEAU AV (SANS CABLE) | E40: F21 | F40: 1 | H40: ='INPUT2 - Veh Sub-Syst Mass'!L158*'INPUT2 - Veh Sub-Syst Mass'!K158+'INPUT2 - Veh Sub-Syst Mass'!L159*'INPUT2 - Veh Sub-Syst Mass'!K159 -> 13.62 | I40: =H40*F40 -> 13.62 | O40: =IF(ISBLANK(M40),"/",1/M40*(I40-M40)) -> /
C41: HYD | D41: ELEMENT SUSPENSION AV HYDROPNEUMATIQUE | E41: E16 | F41: 0.7 | I41: =H41*F41 -> 0 | O41: =IF(ISBLANK(M41),"/",1/M41*(I41-M41)) -> /
C42: LAS | D42: BERCEAU – TRAVERSE TRAIN AV | E42: E11 | F42: 0 | H42: ='INPUT2 - Veh Sub-Syst Mass'!L200*'INPUT2 - Veh Sub-Syst Mass'!K200 -> 22.9 | I42: =H42*F42 -> 0 | O42: =IF(ISBLANK(M42),"/",1/M42*(I42-M42)) -> /
C43: LAS | D43: TRIANGLE BRAS ESSIEU RIGIDE | E43: E12 | F43: 0.4 | H43: ='INPUT2 - Veh Sub-Syst Mass'!L202*'INPUT2 - Veh Sub-Syst Mass'!K202 -> 8.1 | I43: =H43*F43 -> 3.24 | O43: =IF(ISBLANK(M43),"/",1/M43*(I43-M43)) -> /
C44: LAS | D44: ELEMENT SUSPENSION AV METALLIQUE | E44: E14 | F44: 0.8 | H44: ='INPUT2 - Veh Sub-Syst Mass'!L198*'INPUT2 - Veh Sub-Syst Mass'!K198 -> 22.7 | I44: =H44*F44 -> 18.16 | O44: =IF(ISBLANK(M44),"/",1/M44*(I44-M44)) -> /
C45: LAS | D45: ANTIDEVERS AV | E45: E15 | F45: 0.2 | H45: ='INPUT2 - Veh Sub-Syst Mass'!L203*'INPUT2 - Veh Sub-Syst Mass'!K203 -> 5 | I45: =H45*F45 -> 1 | O45: =IF(ISBLANK(M45),"/",1/M45*(I45-M45)) -> /
I46: =H46*F46 -> 0 | O46: =IF(ISBLANK(M46),"/",1/M46*(I46-M46)) -> /
...

Sheet OUTPUT - Mass & CoG
D2: PROGRAM : | E2: ='INPUT1 - Veh Geometry'!H8 -> STLA-S | H2: PROJECT : | I2: ='INPUT1 - Veh Geometry'!I8 -> J1X MHEV P2 FWD | L2: MODEL : | O2: ='INPUT1 - Veh Geometry'!J8 -> L2
B4: Mass & CoG Synthesis :
C6: A) CURB WEIGHT LOAD CASE
H8: MASS : | L8: COG POSITION
O9: Wheels at 'REF load case' position | Q9: Wheels at 'CURB load case' position
D10: Curb weight : | H10: Total Veh | I10: Front | J10: Rear | L10: X | M10: Y | O10: Z / veh referential | Q10: Z / veh referential | S10: Z / ground
D11: Masses Suspendues / Sprung mass : | H11: ='INPUT2 - Veh Sub-Syst Mass'!D276 -> 1245.005 | I11: ='INPUT2 - Veh Sub-Syst Mass'!F276 -> 774.56829 | J11: ='INPUT2 - Veh Sub-Syst Mass'!H276 -> 470.43671 | L11: ='INPUT2 - Veh Sub-Syst Mass'!O276 -> 955.04854 | M11: ='INPUT2 - Veh Sub-Syst Mass'!Q276 -> -25.234291 | O11: ='INPUT2 - Veh Sub-Syst Mass'!S276 -> 289.2012 | Q11: =+'INPUT2 - Veh Sub-Syst Mass'!T276 -> 289.14878
D13: Masses Non Suspendues / Unsprung mass : | F13: Front axle | H13: ='INPUT2 - Veh Sub-Syst Mass'!D268 -> 109.94 | I13: ='INPUT2 - Veh Sub-Syst Mass'!F268 -> 110.55152 | J13: ='INPUT2 - Veh Sub-Syst Mass'!H268 -> -0.61151515 | L13: ='INPUT2 - Veh Sub-Syst Mass'!O268 -> -57.184373 | M13: ='INPUT2 - Veh Sub-Syst Mass'!Q268 -> 0 | O13: ='INPUT2 - Veh Sub-Syst Mass'!S268 -> 110.34131 | Q13: ='INPUT2 - Veh Sub-Syst Mass'!T268 -> 92.163398
F14: Rear axle | H14: ='INPUT2 - Veh Sub-Syst Mass'!D269 -> 101.344 | I14: ='INPUT2 - Veh Sub-Syst Mass'!F269 -> -3.0636837 | J14: ='INPUT2 - Veh Sub-Syst Mass'!H269 -> 104.40768 | L14: ='INPUT2 - Veh Sub-Syst Mass'!O269 -> 2677.3086 | M14: ='INPUT2 - Veh Sub-Syst Mass'!Q269 -> 0 | O14: ='INPUT2 - Veh Sub-Syst Mass'!S269 -> 78.236442 | Q14: ='INPUT2 - Veh Sub-Syst Mass'!T269 -> 38.051246
F15: Total | H15: =H13+H14 -> 211.284 | I15: =I13+I14 -> 107.48783 | J15: =J13+J14 -> 103.79617 | L15: =($H13*L13+$H14*L14)/$H15 -> 1254.4363 | M15: =($H13*M13+$H14*M14)/$H15 -> 0 | O15: =($H13*O13+$H14*O14)/$H15 -> 94.941964 | Q15: =($H13*Q13+$H14*Q14)/$H15 -> 66.208087
D17: Total Veh / Sprung + Unsprung : | H17: =H11+H13+H14 -> 1456.289 | I17: =I11+I13+I14 -> 882.05612 | J17: =J11+J13+J14 -> 574.23288 | L17: ='INPUT2 - Veh Sub-Syst Mass'!O274 -> 998.48486 | M17: ='INPUT2 - Veh Sub-Syst Mass'!Q274 -> -21.573203 | O17: ='INPUT2 - Veh Sub-Syst Mass'!S274 -> 261.01732 | Q17: =SUMPRODUCT(H11:H14,Q11:Q14)/SUM(H11:H14) -> 256.80369 | S17: =Q17-H26+((L17-'INPUT1 - Veh Geometry'!H61)/'INPUT1 - Veh Geometry'!H33)*(H26-I26) -> 558.6615
H19: Ft repartition : | I19: =I17/H17 -> 0.60568755
D21: Output for 'Lot A' :
H23: Front (ZA1) | I23: Rear (ZA2)
D24: Position centre Roue - ZA theo (Curb mass load case) | H24: ='INPUT1 - Veh Geometry'!J61-'INPUT1 - Veh Geometry'!J62+'INPUT1 - Veh Geometry'!J63 -> 45 | I24: ='INPUT1 - Veh Geometry'!J72-'INPUT1 - Veh Geometry'!J73+'INPUT1 - Veh Geometry'!J74 -> 25
D25: Rayon du pneu sous charge (Curb mass load case) | H25: ='INPUT1 - Veh Geometry'!H83+6 -> 339 | I25: ='INPUT1 - Veh Geometry'!I83+6 -> 343
D26: Z sol dans rep véh. (Curb mass load case) | H26: ='INPUT1 - Veh Geometry'!J63 -> -292 | I26: ='INPUT1 - Veh Geometry'!J74 -> -317
C30: B) GROSS VEHICLE WEIGHT LOAD CASE
H32: MASS : | L32: COG POSITION
O33: Wheels at 'REF load case' position | Q33: Related to GVW load case ground
D34: GVW : | H34: Total Veh | I34: Front | J34: Rear | L34: X | M34: Y | O34: Z / veh referential | Q34: Z / veh referential | S34: Z / ground
D35: Masses Suspendues / Sprung mass : | H35: ='INPUT2 - Veh Sub-Syst Mass'!D276+SUM('INPUT2 - Veh Sub-Syst Mass'!D279:D283) -> 1716.009 | I35: ='INPUT2 - Veh Sub-Syst Mass'!F276+SUM('INPUT2 - Veh Sub-Syst Mass'!F279:F283) -> 885.20715 | J35: ='INPUT2 - Veh Sub-Syst Mass'!H276+SUM('INPUT2 - Veh Sub-Syst Mass'!H279:H283) -> 830.80185 | L35: =($H41*L41-$H37*L37-$H38*L38)/$H35 -> 1235.65 | M35: =($H41*M41-$H37*M37-$H38*M38)/$H35 -> -18.308073 | O35: =($H41*O41-$H37*O37-$H38*O38)/$H35 -> 317.67196 | Q35: =($H41*Q41-$H37*Q37-$H38*Q38)/$H35 -> 317.66719
D37: Masses Non Suspendues / Unsprung mass : | F37: Front axle | H37: =H13 -> 109.94 | I37: =I13 -> 110.55152 | J37: =J13 -> -0.61151515 | L37: =L13 -> -57.184373 | M37: =M13 -> 0 | O37: =O13 -> 110.34131 | Q37: ='INPUT2 - Veh Sub-Syst Mass'!U268 -> 113.64639
F38: Rear axle | H38: =H14 -> 101.344 | I38: =I14 -> -3.0636837 | J38: =J14 -> 104.40768 | L38: =L14 -> 2677.3086 | M38: =M14 -> 0 | O38: =O14 -> 78.236442 | Q38: ='INPUT2 - Veh Sub-Syst Mass'!U269 -> 102.66274
F39: Total | H39: =H37+H38 -> 211.284 | I39: =I37+I38 -> 107.48783 | J39: =J37+J38 -> 103.79617 | L39: =($H37*L37+$H38*L38)/$H39 -> 1254.4363 | M39: =($H37*M37+$H38*M38)/$H39 -> 0 | O39: =($H37*O37+$H38*O38)/$H39 -> 94.941964 | Q39: =($H37*Q37+$H38*Q38)/$H39 -> 108.378
D41: Total Veh / Sprung + Unsprung : | H41: ='INPUT2 - Veh Sub-Syst Mass'!D284 -> 1927.293 | I41: ='INPUT2 - Veh Sub-Syst Mass'!F284 -> 992.69498 | J41: ='INPUT2 - Veh Sub-Syst Mass'!H284 -> 934.59802 | L41: ='INPUT2 - Veh Sub-Syst Mass'!O284 -> 1237.7095 | M41: ='INPUT2 - Veh Sub-Syst Mass'!Q284 -> -16.301008 | O41: ='INPUT2 - Veh Sub-Syst Mass'!S284 -> 293.25466 | Q41: ='INPUT2 - Veh Sub-Syst Mass'!U284 -> 294.72338 | S41: =Q41-H45+((L41-'INPUT1 - Veh Geometry'!H61)/'INPUT1 - Veh Geometry'!H33)*(H45-I45) -> 545.69061
H43: Ft repartition : | I43: =I41/H41 -> 0.51507217
D45: Z sol dans rep véh. (GVW load case) | H45: ='INPUT1 - Veh Geometry'!J64 -> -266 | I45: ='INPUT1 - Veh Geometry'!J75 -> -235
C49: C) 1P5L LOAD CASE
H51: MASS : | L51: COG POSITION
O52: Wheels at 'REF load case' position | Q52: Wheels at 'CURB load case' position
D53: 1P5L : | H53: Total Veh | I53: Front | J53: Rear | L53: X | M53: Y | O53: Z / veh referential | Q53: Z / veh referential | S53: Z / ground
D54: Curb mass (total vehicle) : | H54: =H17 -> 1456.289 | I54: =I17 -> 882.05612 | J54: =J17 -> 574.23288 | L54: =L17 -> 998.48486 | M54: =M17 -> -21.573203 | O54: =O17 -> 261.01732 | Q54: =Q17 -> 256.80369
D55: - 1 passenger | H55: ='INPUT1 - Veh Geometry'!G15 -> 75 | I55: =H55-J55 -> 35.894886 | J55: =H55*(L55-'INPUT1 - Veh Geometry'!$H$61)/'INPUT1 - Veh Geometry'!$H$33 -> 39.105114 | L55: ='INPUT1 - Veh Geometry'!H42 -> 1334 | M55: ='INPUT1 - Veh Geometry'!I42 -> -355 | O55: ='INPUT1 - Veh Geometry'!J42 -> 390.3 | Q55: =O55 -> 390.3
D56: - 5 liter of fuel only | H56: =-('INPUT2 - Veh Sub-Syst Mass'!L28-5*0.75) -> 3.75 | I56: =H56-J56 -> 0.90553977 | J56: =H56*(L56-'INPUT1 - Veh Geometry'!$H$61)/'INPUT1 - Veh Geometry'!$H$33 -> 2.8444602 | L56: ='INPUT1 - Veh Geometry'!H56 -> 1960 | M56: ='INPUT1 - Veh Geometry'!I56 -> 38 | O56: ='INPUT1 - Veh Geometry'!J56 -> 33 | Q56: =O56 -> 33
D58: Total Veh (1P5L) : | H58: =H54+H55+H56 -> 1535.039 | I58: =I54+I55+I56 -> 918.85655 | J58: =J54+J55+J56 -> 616.18245 | L58: =($H54*L54+$H55*L55+$H56*L56)/$H58 -> 1017.2266 | M58: =($H54*M54+$H55*M55+$H56*M56)/$H58 -> -37.718467 | O58: =($H54*O54+$H55*O55+$H56*O56)/$H58 -> 266.77687 | Q58: =($H54*Q54+$H55*Q55+$H56*Q56)/$H58 -> 262.77941
H60: Ft repartition : | I60: =I58/H58 -> 0.5985884
B67: Bilan par périmètre (estimé, pour info) / Assesment per perimeter, for information
D69: Top Hat : | H69: SOEE | I69: =SUMIF('INPUT2 - Veh Sub-Syst Mass'!$Z$6:$Z$252,"SOEE",'INPUT2 - Veh Sub-Syst Mass'!$Y$6:$Y$252) -> 220.362
H70: SCEG | I70: =SUMIF('INPUT2 - Veh Sub-Syst Mass'!$Z$6:$Z$252,"SCEG",'INPUT2 - Veh Sub-Syst Mass'!$Y$6:$Y$252) -> 398.501
...

Sheet Vide

Sheet DEC5 <--> A2MAC1 Dictionary
A2: IMPORTANT : Last update of DEC5 <--> A2MAC1 Dictionary is stored into document : 00987_22_00053
A4: Lot | B4: Pièce | C4: Découpage | D4: Check | E4: Lot + Dec | F4: Niv 1 | G4: Niv 2
A5: --- | B5: AFFECTATION LOT/DECOUPAGE NON PREVUE | C5: 0_Total | E5: --- 0_Total
A6: ABA | B6: CONDITIONNEMENT | C6: 83G | D6: ok | E6: ABA 83G | F6: NON AFFECTE
A7: ABA | B7: PIECES VEHICULE REPETITIVES (OU A CARACTERE REPETITIF) | C7: 73R | D7: ok | E7: ABA 73R | F7: BV | G7: BVA
A8: ABA | B8: CONVERTISSEUR | C8: C12 | D8: ok | E8: ABA C12 | F8: BV | G8: BVA
A9: ABA | B9: COUPLEUR | C9: C13 | D9: ok | E9: ABA C13 | F9: BV | G9: BVA
A10: ABA | B10: BOITE VITESSES AUTOMATIQUE | C10: C24 | D10: ok | E10: ABA C24 | F10: BV | G10: BVA
A11: ABA | B11: PILOTAGE ELECTRONIQUE TRANSMISSION AUTOMATIQUE | C11: C26 | D11: ok | E11: ABA C26 | F11: BV | G11: BVA
A12: ABA | B12: CARTER BOITE VITESSES AUTOMATIQUE | C12: C27 | D12: ok | E12: ABA C27 | F12: BV | G12: BVA
A13: ABA | B13: VARIATEUR TRANSMISSION CONTINU | C13: C28 | D13: ok | E13: ABA C28 | F13: BV | G13: BVA
A14: ABA | B14: EQUIPEMENT ELECTRIQUE BOITE VITESSES | C14: C29 | D14: ok | E14: ABA C29 | F14: BV | G14: BVA
A15: ABA | B15: MARQUAGE TRANSMISSION | C15: C91 | D15: ok | E15: ABA C91 | F15: BV | G15: BVA
A16: ABA | B16: MONTAGE BOITE VITESSES AUTOMATIQUE | C16: CZC | D16: ok | E16: ABA CZC | F16: BV | G16: BVA
A17: ABA | B17: NON REPARTI | C17: NR- | D17: ok | E17: ABA NR- | F17: BV | G17: BVA
A18: AEE | B18: COMPOSANTS FAISCEAUX | C18: 73F | D18: ok | E18: AEE 73F | F18: NON AFFECTE
A19: AEE | C19: 0_Total
A20: AEE | B20: CONDITIONNEMENT | C20: 83G | D20: ok | E20: AEE 83G | F20: NON AFFECTE
A21: AEE | B21: STG ARCHITECTURE ELECTRICITE ELECTRONIQUE | C21: 98B | D21: ok | E21: AEE 98B | F21: NON AFFECTE
A22: AEE | B22: PIECES VEHICULE REPETITIVES (OU A CARACTERE REPETITIF) | C22: 73R | D22: ok | E22: AEE 73R | F22: FAISCEAUX | G22: Faisceau
A23: AEE | B23: ALLUMAGE | C23: A33 | D23: ok | E23: AEE A33 | F23: GMP
A24: AEE | B24: EQUIPEMENT DIESEL | C24: A34 | D24: ok | E24: AEE A34 | F24: GMP
A25: AEE | B25: BOITIER PILOTAGE ELECTRONIQUE MULTIFONCTIONNEL (MECANIQUE) | C25: A36 | D25: ok | E25: AEE A36 | F25: GMP
A26: AEE | B26: PILOTAGE ELECTRONIQUE TRANSMISSION AUTOMATIQUE | C26: C26 | D26: ok | E26: AEE C26 | F26: DIVERS EE
A27: AEE | B27: NON REPARTI | C27: NR- | D27: ok | E27: AEE NR- | F27: DIVERS EE
A28: AEE | B28: EQUIPEMENT ELECTRIQUE ASSISE AV | C28: Y1L | D28: ok | E28: AEE Y1L | F28: ASSISES | G28: ASSISE AV
A29: AEE | B29: EQUIPEMENT ELECTRIQUE ASSISE AR | C29: Y2K | D29: ok | E29: AEE Y2K | F29: ASSISES | G29: ASSISE AR RG2
A30: AEE | B30: FIXATION – REFROIDISSEMENT BATTERIE | C30: Z1B | D30: ok | E30: AEE Z1B | F30: BATTERIE
A31: AEE | B31: ELEMENTS COMMUNS 3Z1 | C31: Z1Z | E31: AEE Z1Z | F31: NON AFFECTE
A32: AEE | B32: SUPPORT BATTERIE (SI AMOVIBLE) | C32: Z1C | D32: ok | E32: AEE Z1C | F32: BATTERIE
A33: AEE | B33: EQUIPEMENT ELECTRIQUE PROTECTION – DERIVATION | C33: Z5U | D33: ok | E33: AEE Z5U | F33: DIVERS EE | G33: Système porte fusibles/relais
A34: AEE | B34: CABLAGE BATTERIE SERVITUDE – TRACTION | C34: Z9A | D34: ok | E34: AEE Z9A | F34: FAISCEAUX | G34: Câblage de puissance
A35: AEE | B35: RANGEMENT ELECTRICITE – ELECTRONIQUE (BOITE, SUPPORT) | C35: Z9F | D35: ok | E35: AEE Z9F | F35: DIVERS EE
A36: AEE | B36: ELEMENT CONNEXION ET RELAIS MULTIFONCTIONNEL | C36: Z9G | D36: ok | E36: AEE Z9G | F36: DIVERS EE
A37: AEE | B37: FAISCEAU MOTEUR | C37: Z9J | D37: ok | E37: AEE Z9J | F37: FAISCEAUX | G37: Faisceau
A38: AEE | B38: FAISCEAU EQUIPEMENT MECANIQUE – MOTEUR | C38: Z9K | D38: ok | E38: AEE Z9K | F38: FAISCEAUX | G38: Faisceau
A39: AEE | B39: FAISCEAU PRINCIPAL | C39: Z9L | D39: ok | E39: AEE Z9L | F39: FAISCEAUX | G39: Faisceau
A40: AEE | B40: FAISCEAU FACADE AV | C40: Z9M | D40: ok | E40: AEE Z9M | F40: FAISCEAUX | G40: Faisceau
A41: AEE | B41: FAISCEAU PLANCHE BORD | C41: Z9N | D41: ok | E41: AEE Z9N | F41: FAISCEAUX | G41: Faisceau
A42: AEE | B42: FAISCEAU ACCES AR | C42: Z9P | D42: ok | E42: AEE Z9P | F42: FAISCEAUX | G42: Faisceau
...

Sheet A2MAC1 MICV Std bookmark
B2: -1 | C2: ADAPTATION
B3: -1 | C3: =D3 -> ADDBLUE | D3: ADDBLUE
B4: -1 | C4: =D4 -> CARBURANT | D4: CARBURANT
B5: -1 | C5: =D5 -> CIRCUIT AIR | D5: CIRCUIT AIR
B6: -1 | C6: =D6 -> CIRCUIT EAU | D6: CIRCUIT EAU
B7: -1 | C7: =D7 -> COMMANDE VITESSE | D7: COMMANDE VITESSE
B8: -1 | C8: =D8 -> ECHAPPEMENT | D8: ECHAPPEMENT
B9: -1 | C9: =D9 -> ECRANS THERMIQUE | D9: ECRANS THERMIQUE
B10: -1 | C10: =D10 -> FACADE | D10: FACADE
B11: -1 | C11: =D11 -> LIQUIDE ADDITIF | D11: LIQUIDE ADDITIF
B12: -1 | C12: =D12 -> LIQUIDE REFROIDISSEMENT | D12: LIQUIDE REFROIDISSEMENT
B13: -1 | C13: =D13 -> PEDALIER | D13: PEDALIER
B14: -1 | C14: =D14 -> RESERVOIR ADDITIF | D14: RESERVOIR ADDITIF
... B17: 3123 | C17: =D17 -> Système de refroidissement par huile | D17: Système de refroidissement par huile
B18: -1 | C18: ADTH
B19: -1 | C19: =D19 -> DIVERS ADTH | D19: DIVERS ADTH
B20: -1 | C20: =D20 -> GROUP CLIM | D20: GROUP CLIM
B21: -1 | C21: =D21 -> COMPRESSEUR CLIM | D21: COMPRESSEUR CLIM
B22: -1 | C22: =D22 -> GROUPE ADDITIONNEL | D22: GROUPE ADDITIONNEL
B23: -1 | C23: AILES
B24: 13885 | C24: =D24 -> Ailes avant | D24: Ailes avant
B25: 14859 | C25: =D25 -> Ailes arrière | D25: Ailes arrière
B26: 2432 | C26: =D26 -> Avant gauche (ancien process) | D26: Avant gauche (ancien process)
B27: 2431 | C27: =D27 -> Avant droite (ancien process) | D27: Avant droite (ancien process)
B28: -1 | C28: ALTERNATEUR
B29: 6208 | C29: =D29 -> Système alternateur | D29: Système alternateur
B30: -1 | C30: ASSISES
B31: -1 | C31: =D31 -> ASSISE AR RG2 | D31: ASSISE AR RG2
B32: -1 | C32: =D32 -> ASSISE AR RG3 | D32: ASSISE AR RG3
B33: -1 | C33: =D33 -> ASSISE AV | D33: ASSISE AV
B34: 9573 | C34: =D34 -> Fixations ISOFIX | D34: Fixations ISOFIX
B35: -1 | C35: ATTELAGE
B36: 5541 | C36: =D36 -> Système crochet d attelage / Porte vélo | D36: Système crochet d attelage / Porte vélo
B37: -1 | C37: BATTERIE
B38: 2131 | C38: =D38 -> Système batterie 12V | D38: Système batterie 12V
B39: -1 | C39: BATTERIE TRACTION
B40: 11460 | C40: =D40 -> Système batterie traction | D40: Système batterie traction
B41: 30155 | C41: =D41 -> Système module de charge HT | D41: Système module de charge HT
B42: 18975 | C42: =D42 -> Durite de ventilation module charge HT | D42: Durite de ventilation module charge HT
B43: 30029 | C43: =D43 -> Calculateur gestion batterie HT | D43: Calculateur gestion batterie HT
...

Sheet V2.0 update follow-up
B3: Outil de référence WGHT : Outil_eval_CdG_V1.0.xlsx (00987_19_00164)
B4: Problème à traiter : | C4: Qui a rencontré / Quand : | D4: Action de progrès : | E4: Pilote / Quand : | F4: Avancement :
A5: 1 | B5: Problème : Importantes variations de x/z cdg (de l’ordre de 20mm en Z) entre les estimations AVP au JAP, les remontages RdfnU, puis TKO sur les silhouettes P64 (Bev principalement). | C5: Grégory / Yvan / Thierry | D5: Quoi : Robustifier les hypothèses de positionnement des masses des sous-système : | E5: Gilles / août-22 | F5: 10/08/2022 : - Revue globale de l'outil réalisée (correction erreurs formules, réaffectation de sous-systèmes, adaptation des facteurs de positionnement des Cdg). - Test réalisé pour un P64 BEV AWD Level3 à partir du fichier de remontage numérique MCI_SS_ENS_P64_TKO_BEV_AWD_LEVEL3_V3.xlsm (docinfo : 00987_22_00103). --> Résultats obtenus : - MAV : 2262,3kg (2263,2mm au remontage num) - X CdG : 1238mm (1221mm au remontage num) --> Attention Cdg à 1330mm dans Cas deCahrge P64. - Y Cdg : -3,5mm (-3,7mm au remontagenum ) - Z cdg : 246,7mm (245,6mm dau remontage num)
B6: Causes identifiées : | D6: Comment :
B7: 1) Trop d’écarts entre le véhicule à estimer (P64 Bev) et le véhicule de référence (P84 ICE). Manque de retex/connaissance pour correctement estimer les briques du cascading en AVP. | D7: - Tester l’outil avec un P64 BEV AWD à Injecter les valeurs du 1/5ième + DEC5 + positions issues des remontages numériques TKO.
B8: 2) Les hypothèses utilisées par l’outil (positionnement par lot) ne sont pas nécessairement ‘juste’. | D8: - Analyser les écarts et corriger les positionnements des CDG
D9: - Compléter la liste des inputs si nécessaire.
A10: 2 | B10: Problème : Le contenu de chaque découpage utilisé dans l’outil n’est pas toujours explicite et trivial à interpréter à Risque d’erreur d’interprétation. | C10: Grégory / Yvan / Thierry | D10: Quoi : Clarifier le contenu de chaque sous-système A2MAC1 utilisé dans l’outils AVP. | E10: Gilles / août-22 | F10: 12/08/2022 : - Copie du dictionnaire DEC5 <--> A2MAC1 intégré dans l'outil. Avec rappel lien vers version officielle. - Reste à faire : 1) Reprendre la table de l'onglet 'INPUTS 2' afin qu'elle soit strictement identique au Bookmark MICV A2MAC1. --> Voir nécessité. 2) Ajouter liste des DEC5 en face de chaque sous-système.
D11: Comment :
D12: - Mettre à disposition dans l’outil la table d’équivalence construite pour l’outil Benchmark à Clairement notifier le lien vers la table de référence à jour dans l’outil Bench.
D13: - Etudier faisabilité / Utilité de lister les codes découpage xPSA en face de chaque ligne de l’onglet ‘Evaluation’
A14: 3 | B14: Problème : Il est nécessaire re remplir manuellement toutes les masses des sous-systèmes lorsque le veh de réf n’a pas été démonté par A2MAC1. | D14: Quoi : Permettre d’injecter directement dans l’onglet Evaluation les masses converties d’un DEC5 vers un découpage A2MAC1. | E14: Olivier + Laurent
D15: Comment : | E15: 44805
D16: - Compléter la matrice d’équivalence DEC5 à A2MAC1 pour intégrer les niveaux 3 et 4 (quand nécessaire).
D17: - Gérer dans l’outil Bench deux tableaux de sortie DEC5 à A2MAC1 (1 avec les niveaux 1 et 2, l’autre avec les niveaux 1 à 4).
A18: 4 | B18: Problème : Le calcul des MNS est ‘caché’, nécessite de rigoureusement détailler les masses des sous-systèmes. | D18: Quoi : Mettre en évidence les inputs utilisées pour calculer les MNS et visualiser les écarts avec le véhicule de référence. | E18: Gilles / août-22 | F18: 10/08/2022 : - Traité. - Intégré dans fichier version docinfo à partir de v2.0.
B19: Problèmes : Le contrôle de la justesse des MNS sorties par l’outil n’est pas ‘instantané’. | D19: Comment : - Remettre en forme et rendre visible le calcul des MNS.
D20: - Reprendre le formalisme d’un DEC5.
D21: - Afficher une comparaison des MNS estimées avec celles du véhicule de ref (format DEC5).
A22: 5 | B22: Problème : Les données relatives aux moteurs (masses et cdg) référencées dans l’onglet ‘Input Data’ ne sont pas nécessairement à jour et leur prise en compte (position) reste macro. | D22: Quoi : Assurer l’utilisation de données ‘moteur’ à jour. Assurer une correcte répartition dans le véhicule. | E22: Gilles Sept-Oct-22 | F22: 12/08/2022 : - Reste à faire = Mettre à jour les CdG des différentes motorisations à partir de la BDD : 00987_15_00582 21/11/2022 : - Mise à jour à partir de la BDD moteur effectuée.
D23: Comment :
D24: - Mise à jour des inputs et des formules de prise en compte.
D25: - Intégration plus précise des différents motorisations électriques.
A26: 6 | B26: Problème : L’estimation du Zcdg par rapport au sol doit être consommée avec précaution car elle fait appel à des données d’entrée non nécessairement vérifiées. | D26: Quoi : Mettre en place un warning sur les données d’entrée du Zcdg (centre d eroue…). | E26: Gilles Sept-Oct-22 | F26: 12/08/2022 : - Changement de la méthode d'estimation du CdG par rapport au sol --> Utilisation de la position des MNS recalée pour chaque sol.
A28: 7 | B28: Problème : L’outil ne génère que des estimations en masse à vide. | D28: Quoi : Intégrer des estimations en MTAC. | E28: Gilles / Nov-22 | F28: 12/08/2022 : - Modification du fichier afin d'estimer la position du CdG en configuration MTAC. - Méthode utilisée = repositionnement de chaque masse non suspendue à partir de l'écart entre le sol de REF et le sol MTAC (calculté en calculant la raideur des suspensions à partir des positions des sols MAV et REF du 1/5ième).
D29: Comment :
D30: - Ajouter une prise en compte des options, passager et EMC.
