Workbook
Name PROBABILITE: '[4]tri eco'!$M$2:$M$8
Name PROBABILITE: '[4]tri eco'!$M$2:$M$8
Name PROBABILITE: '[4]tri eco'!$M$2:$M$8
Name PROBABILITE: '[4]tri eco'!$M$2:$M$8
Name PROBABILITE: 'tri eco'!$M$2:$M$8

Sheet Lien 
B4: SP1 portefolio | C4: http://docinfogroupe.inetpsa.com/ead/doc/ref.00987_24_00014/v.vc/fiche

Sheet Portefeuille SP2
D1: BCI_BODY | E1: TH | Q1: IN PROGRESS | S1: 0
D2: BCI_DOORS | E2: PTF | Q2: DECIDED | S2: 0.25
D3: BCI_FRSD | E3: PRS | Q3: CANCELED | S3: 0.5
D4: BCI_EMC | Q4: IN STATUS | S4: 0.75
D5: BCI_SEATS/TRIMS | S5: 1
D6: BCI_PDB/CONSOLE
D7: BCI_DOORS_INT
D8: BCI_CHASSIS
D9: SWX_EHE
D10: PRS_PHES
D11: PRS_PPM
D12: PRS_EDM
D13: PRS_BATT
A14: Topic Nr | B14: Creation Date | C14: Responsible | D14: Functions | E14: BVH / PWT / Tophat | F14: RESp | G14: Désignation : Ensemble / Piéces FR | H14: Désignation : Ensemble / Piéces ENG | I14: Description | J14: Comments BCI SPC_1 | K14: Date | L14: Mass comments (changes, dates, …) | M14: Invest impact | N14: TPC Impact (€) | O14: Next steps | P14: Decision expected for ? | Q14: COTATION (*) | R14: Priorization | S14: Confidence % | T14: Mass kg (*) | U14: Ponderated mass / Ratio (kg*%) | V14: O3H HR 63 FWD€ | W14: O3H XR 80 FWD€ | X14: O3H XR 80 AWD perfo € | Y14: O3H MHEV FWD€ | Z14: O3H HEV FWD€ | AA14: O3W 63 kWhu LFP FWD€ | AB14: O3W 80 kWhu NMx FWD€ | AC14: O3W MHEV FWD€ | AD14: O3W HEV FWD€ | AE14: P3S HR 63 FWD€ | AF14: P3S XR 80 FWD€ | AG14: P3S XR 80 AWD perfo € | AH14: P3S MHEV FWD€ | AI14: P3S HEV FWD€ | AJ14: P3W 63 kWhu LFP FWD€ | AK14: P3W 80 kWhu NMx FWD€ | AL14: P3W MHEV FWD€ | AM14: P3W HEV FWD€ | AN14: P3U HR 63 FWD€ | AO14: P3U XR 80 FWD€ | AP14: P3U XR 80 AWD perfo € | AQ14: P3U MHEV FWD€ | AR14: P3U HEV FWD€ | AS14: J1X SR FWD€ | AT14: J1X MHEV FWD€ | AU14: J1X MHEV AWD€ | AV14: J1X HEV FWD€ | AW14: J2U HR 63 FWD€ | AX14: J2U XR 80 FWD€ | AY14: J2U MHEV FWD | AZ14: J2U HEV FWD | BA14: J2U HEV AWD
B15: 45632 | C15: SPC_1 | D15: BIW | E15: TH | F15: MICHAEL BORE | G15: activ spoiler | H15: activ spoiler | J15: 06/10/2025 sujet à supprimer car pas d'active Spoiler sur le projet SPC_1 | P15: o | Q15: CANCELED | R15: TBD | S15: 0.8 | T15: 4 | U15: =T15*S15 -> 3.2 | V15: 1 | W15: 1 | X15: 1 | Y15: 1 | Z15: 1 | AA15: 1 | AB15: 1 | AC15: 1 | AD15: 1 | AE15: 1 | AF15: 1 | AG15: 1 | AH15: 1 | AI15: 1 | AJ15: 1 | AK15: 1 | AL15: 1 | AM15: 1 | AN15: 1 | AO15: 1 | AP15: 1 | AQ15: 1 | AR15: 1 | AS15: 1 | AV15: 1 | AW15: 1 | AX15: 1 | AY15: 1 | AZ15: 1 | BA15: 1
A16: 301a | B16: 20/06/2025 | C16: SP1 | D16: FRSD | E16: TH | F16: Sébastien Bonnefoi (P1H)/ Jean Michel Gabus P1X | G16: PC Av / Proj - MS | H16: style/brand | I16: P1HX : Nouvelle face_Av MS | J16: Stratégie projet | L16: 20/06/2025 Retour frns : Proj MS+1,2kg / PC MS+1kg 28/05/2025 à 50% suite 1er retour frns du Proj / En attente info du PC 06/05/2025 passe à 75% 22/04/2025 RD _S16 : Choix Concept Proj (3 parts)_01353_25_00247 24/03/2025 Impact nvo Style_Feu déporté | P16: o | Q16: CANCELED | S16: 1 | T16: 2.2 | U16: =T16*S16 -> 2.2 | V16: 1 | W16: 1 | X16: 1 | Y16: 1 | Z16: 1 | AA16: 1 | AB16: 1 | AC16: 1 | AD16: 1 | AE16: 1 | AF16: 1 | AG16: 1 | AH16: 1 | AI16: 1 | AJ16: 1 | AK16: 1 | AL16: 1 | AM16: 1 | AN16: 1 | AO16: 1 | AP16: 1 | AQ16: 1 | AR16: 1 | AS16: 1 | AV16: 1 | AW16: 1 | AX16: 1 | AY16: 1 | AZ16: 1 | BA16: 1
A17: 220 | B17: 45536 | C17: SPC_1 | D17: BIW | E17: TH | F17: MICHAEL BORE | G17: Pantographe capot | H17: hood Pantographe | I17: imposé par le style | J17: 10/10/2025 référence projet col de cygne, mais demande PEDPRO de Pantographe 11/10/2024 QCTP Pantograh hood hinge =>https://docinfogroupe.stellantis.com/ead/doc/ref.21007_24_00151/v.vc/fiche | K17: PM | M17: =150+200 -> 350 | N17: 8.5 | P17: o | Q17: DECIDED | R17: TBD | S17: 1 | T17: 1 | U17: =T17*S17 -> 1 | V17: 1 | W17: 1 | X17: 1 | Y17: 1 | Z17: 1 | AA17: 1 | AB17: 1 | AC17: 1 | AD17: 1 | AE17: 1 | AF17: 1 | AG17: 1 | AH17: 1 | AI17: 1 | AJ17: 1 | AK17: 1 | AL17: 1 | AM17: 1 | AN17: 1 | AO17: 1 | AP17: 1 | AQ17: 1 | AR17: 1 | AS17: 1 | AV17: 1 | AW17: 1 | AX17: 1 | AY17: 1 | AZ17: 1 | BA17: 1
B18: 45536 | C18: SPC_1 | D18: BIW | E18: TH | F18: MICHAEL BORE | G18: Pare choc | H18: front & rear bumper | I18: nouvelle politique GPC | J18: 06/10/2025 Pas de PORO | M18: 0 | N18: (-6) | P18: o | Q18: DECIDED | R18: TBD | S18: 1 | T18: 0.82 | U18: =T18*S18 -> 0.82 | V18: 1 | W18: 1 | X18: 1 | Y18: 1 | Z18: 1 | AA18: 1 | AB18: 1 | AC18: 1 | AD18: 1 | AE18: 1 | AF18: 1 | AG18: 1 | AH18: 1 | AI18: 1 | AJ18: 1 | AK18: 1 | AL18: 1 | AM18: 1 | AN18: 1 | AO18: 1 | AP18: 1 | AQ18: 1 | AR18: 1 | AS18: 1 | AT18: 1 | AU18: 1 | AV18: 1 | AW18: 1 | AX18: 1 | AY18: 1 | AZ18: 1 | BA18: 1
A19: 322 | B19: 45813 | C19: SP1 | D19: INT - PDB/CONSOLE | E19: TH | F19: FREDERIC BRUNIER | G19: PdB/Console UPPER | H19: Dashboard/Upper console | I19: Chgt de matière (passage du TD 12 vierge au TD12 recyclé / passage du MD20 au TD28 green) | J19: CP P1H Sébastien Dupuis 24/06/2025 à confirmer avec Sébastien car attente panneau SYNC5 et MAJ de la masse | L19: 05/06/2025  Planche de Bord : +0.280 kg / Console UPPER : +0.147 kg et +0.260 kg | P19: o | Q19: CANCELED | S19: 0.75 | T19: 1 | U19: =T19*S19 -> 0.75 | V19: 1 | W19: 1 | X19: 1 | Y19: 1 | Z19: 1 | AA19: 1 | AB19: 1 | AC19: 1 | AD19: 1 | AE19: 1 | AF19: 1 | AG19: 1 | AH19: 1 | AI19: 1 | AJ19: 1 | AK19: 1 | AL19: 1 | AM19: 1 | AN19: 1 | AO19: 1 | AP19: 1 | AQ19: 1 | AR19: 1 | AS19: 1 | AV19: 1 | AW19: 1 | AX19: 1 | AY19: 1 | AZ19: 1 | BA19: 1
A20: 131 | B20: 01/04/2025 | C20: SP1 | D20: Door panel | E20: TH | F20: FREDERIC BRUNIER | G20: Panneau de porte | H20: style/brand | I20: Suppression Textile Fabric | J20: CP P1H Sébastien Dupuis 23/06/25 LM : Vu avec Frédéric refusé par SP1 - A confirmer pour SPC | L20: 01/04/2025 FOAM nécessaire pour process/frn. Et Risque d'ajout d'un tissu embossé sur Portes AV - Demande STYLE, TT niveau -(PTM/VSM) 15/11/2024 Suppression FOAM 14/03/2024 Line-up V9 | P20: o | Q20: CANCELED | S20: 0.25 | T20: 0.1 | U20: =T20*S20 -> 0.025 | V20: 1 | W20: 1 | X20: 1 | Y20: 1 | Z20: 1 | AA20: 1 | AB20: 1 | AC20: 1 | AD20: 1 | AE20: 1 | AF20: 1 | AG20: 1 | AH20: 1 | AI20: 1 | AJ20: 1 | AK20: 1 | AL20: 1 | AM20: 1 | AN20: 1 | AO20: 1 | AP20: 1 | AQ20: 1 | AR20: 1 | AS20: 1 | AV20: 1 | AW20: 1 | AX20: 1 | AY20: 1 | AZ20: 1 | BA20: 1
A21: 132 | B21: 01/04/2025 | C21: SP1 | D21: INT - PDB/CONSOLE | E21: TH | F21: FREDERIC BRUNIER | G21: Pdb_suppression du foam sur les décors textiles | H21: style/brand | I21: suppression du foam sur les décors textiles | J21: CP P1H Sébastien Dupuis 23/06/25 LM : Vu avec Frédéric refusé par SP1 - A confirmer pour SPC | L21: 01/04/2025 Idem Pano Porte 20/09/2024 Passage en PT/VSM CW40 05/09/2024 A revoir avec Guillaume 14/03/2024 Line-up V9 | P21: o | Q21: CANCELED | S21: 0.25 | T21: 0.1 | U21: =T21*S21 -> 0.025 | V21: 1 | W21: 1 | X21: 1 | Y21: 1 | Z21: 1 | AA21: 1 | AB21: 1 | AC21: 1 | AD21: 1 | AE21: 1 | AF21: 1 | AG21: 1 | AH21: 1 | AI21: 1 | AJ21: 1 | AK21: 1 | AL21: 1 | AM21: 1 | AN21: 1 | AO21: 1 | AP21: 1 | AQ21: 1 | AR21: 1 | AS21: 1 | AV21: 1 | AW21: 1 | AX21: 1 | AY21: 1 | AZ21: 1 | BA21: 1
B22: 45546 | C22: SPC_1 | D22: BIW | E22: TH | F22: FRANK BAILLON | G22: Doublure pied central | H22: B pillar inner | I22: stratégie embout Mise en panoplie avec Seatbelt return fix reinforcer | J22: 06/10/2025 a reboucler avec l'embout - Mickael Ludovic DASNOIS | K22: DTM PM-CM | L22: 26/06/2025 a reboucler après hypothèse projet | M22: -350K€ | N22: 2 | P22: x | Q22: DECIDED | R22: TBD | S22: 0.5 | T22: 1.5 | U22: =T22*S22 -> 0.75 | V22: 1 | W22: 1 | X22: 1 | Y22: 1 | Z22: 1 | AA22: 1 | AB22: 1 | AC22: 1 | AD22: 1 | AE22: 1 | AF22: 1 | AG22: 1 | AH22: 1 | AI22: 1 | AJ22: 1 | AK22: 1 | AL22: 1 | AM22: 1 | AN22: 1 | AO22: 1 | AP22: 1 | AQ22: 1 | AR22: 1 | AS22: 1 | AT22: 1 | AU22: 1 | AV22: 1 | AW22: 1 | AX22: 1 | AY22: 1 | AZ22: 1 | BA22: 1
A23: 181 | B23: 46058 | C23: SP1 | D23: BCI_CHASSIS | E23: PTF | G23: Train ar ML : écran aero | H23: Rr axle ML | I23: Demande ajout écran aero sur bras train ML | L23: 27/11/2025 : Présentation en VSM/PTM. Gain important en Aero, mais cout important (+3,5€). Besoin à confirmer après essai, pas en ref en ce moment. Nouvelle estimation à 0,5 kg 03/10/2025 : Aero demande des écrans sur les bras du ML. Demande à confirmer. | P23: o | Q23: IN PROGRESS | S23: 0.75 | T23: 0 | U23: =T23*S23 -> 0 | V23: 1 | W23: 1 | X23: 1 | Y23: 1 | Z23: 1 | AA23: 1 | AB23: 1 | AC23: 1 | AD23: 1 | AE23: 1 | AF23: 1 | AG23: 1 | AH23: 1 | AI23: 1 | AJ23: 1 | AK23: 1 | AL23: 1 | AM23: 1 | AN23: 1 | AO23: 1 | AP23: 1 | AQ23: 1 | AR23: 1 | AS23: 1 | AT23: 1 | AU23: 1 | AV23: 1 | AW23: 1 | AX23: 1 | AY23: 1 | AZ23: 1 | BA23: 1
A24: 202 | B24: 11/06/2025 | C24: SP1 | D24: DIW | E24: TH | F24: Filipe Goncalves (P1H)/ Cyrille P1X | G24: Rft Choc LAT Porte AV | H24: BIW/ DIW process | I24: Embout à chaud PHS950 YS1500T => PHS1400-Y1800T et réduction épaisseur | J24: déjà intégré dans la BDD SP2 - ligne à supprimer | L24: 02/07/2025 CANCELLED : Ep.mini déjà atteinte (chgt de matière possible mais aurait nécessité une dimintution d'épasisseur) 11/06/2025 A ré-évaluer 04/11/2024 Idem post Go-Calcul SYNC3 08/07/2024 Retour calcul SYNC3 (Go calcul Nov => 2025?) Pièce en Embout à chaud | P24: o | Q24: CANCELED | S24: 0.5 | T24: -0.1 | U24: =T24*S24 -> -0.05 | V24: 1 | W24: 1 | X24: 1 | Y24: 1 | Z24: 1 | AA24: 1 | AB24: 1 | AC24: 1 | AD24: 1 | AE24: 1 | AF24: 1 | AG24: 1 | AH24: 1 | AI24: 1 | AJ24: 1 | AK24: 1 | AL24: 1 | AM24: 1 | AN24: 1 | AO24: 1 | AP24: 1 | AQ24: 1 | AR24: 1 | AS24: 1 | AV24: 1 | AW24: 1 | AX24: 1 | AY24: 1 | AZ24: 1 | BA24: 1
B25: 45536 | C25: SPC_1 | D25: BIW | E25: TH | F25: MICHAEL BORE | G25: Rear quarter GLASS | H25: Rear quarter GLASS | I25: Part addition for style | J25: 06/10/2025 OK pour P3U et J2U | K25: PM-CM | L25: 26/06/2025 a reboucler après hypothèse projet | M25: 690K€ | N25: 27.1 | P25: o | Q25: DECIDED | R25: TBD | S25: 0.75 | T25: 1 | U25: =T25*S25 -> 0.75 | V25: 1 | W25: 1 | X25: 1 | Y25: 1 | Z25: 1 | AA25: 1 | AB25: 1 | AC25: 1 | AD25: 1 | AE25: 1 | AF25: 1 | AG25: 1 | AH25: 1 | AI25: 1 | AJ25: 1 | AK25: 1 | AL25: 1 | AM25: 1 | AN25: 1 | AO25: 1 | AP25: 1 | AQ25: 1 | AR25: 1 | AS25: 1 | AT25: 1 | AU25: 1 | AV25: 1 | AW25: 1 | AX25: 1 | AY25: 1 | AZ25: 1 | BA25: 1
A26: 215 | B26: 46058 | C26: SP1 | D26: SWX/EE | E26: PTF | G26: Goulotte faisceaux moteur | H26: ENGINE CABLE DUCT | I26: Optimisation | L26: 25/09/2024 : Compté dans le périmètre TH. 18/07/2024 : issu GT EE scope du 15/07/2024 | P26: o | Q26: IN PROGRESS | S26: 0.5 | T26: 0.02 | U26: =T26*S26 -> 0.01 | V26: 1 | W26: 1 | X26: 1 | Y26: 1 | Z26: 1 | AA26: 1 | AB26: 1 | AC26: 1 | AD26: 1 | AE26: 1 | AF26: 1 | AG26: 1 | AH26: 1 | AI26: 1 | AJ26: 1 | AK26: 1 | AL26: 1 | AM26: 1 | AN26: 1 | AO26: 1 | AP26: 1 | AQ26: 1 | AR26: 1 | AS26: 1 | AT26: 1 | AU26: 1 | AV26: 1 | AW26: 1 | AX26: 1 | AY26: 1 | AZ26: 1 | BA26: 1
A27: 224 | B27: 25/09/2024 | C27: SP1 | D27: ICDV | E27: TH | G27: Pneu | I27: Optim de masse 17" et 18" | L27: 25/09/2024 reporté S40 02/09/2024 besoin anayse VDYN 12/06/2024 New / attente retour frns | P27: o | Q27: CANCELED | S27: 0.5 | T27: -1.2 | U27: =T27*S27 -> -0.6 | V27: 1 | W27: 1 | X27: 1 | Y27: 1 | Z27: 1 | AA27: 1 | AB27: 1 | AC27: 1 | AD27: 1 | AE27: 1 | AF27: 1 | AG27: 1 | AH27: 1 | AI27: 1 | AJ27: 1 | AK27: 1 | AL27: 1 | AM27: 1 | AN27: 1 | AO27: 1 | AP27: 1 | AQ27: 1 | AR27: 1 | AS27: 1 | AV27: 1 | AW27: 1 | AX27: 1 | AY27: 1 | AZ27: 1 | BA27: 1
A28: 271 | B28: 08/04/2025 | C28: SP1 | D28: BIW | E28: TH | F28: Franck Baillon (SP1)/ Cyrille P1X | G28: Zone Auvent | H28: new part | I28: Ajout pièces | J28: ???? Déjà sur SP2 | L28: 08/04/2025 Détail : Finition LAT D/G Grille Entrée Air / Grille Entrée Air / Deflect Eau / Etanchéité D/G Grille / Conduit Entrée Air 22/11/2024 Complétude de BOM | P28: o | Q28: DECIDED | S28: 1 | T28: 0.54 | U28: =T28*S28 -> 0.54 | V28: 1 | W28: 1 | X28: 1 | Y28: 1 | Z28: 1 | AA28: 1 | AB28: 1 | AC28: 1 | AD28: 1 | AE28: 1 | AF28: 1 | AG28: 1 | AH28: 1 | AI28: 1 | AJ28: 1 | AK28: 1 | AL28: 1 | AM28: 1 | AN28: 1 | AO28: 1 | AP28: 1 | AQ28: 1 | AR28: 1 | AS28: 1 | AT28: 1 | AU28: 1 | AV28: 1 | AW28: 1 | AX28: 1 | AY28: 1 | AZ28: 1 | BA28: 1
A29: 323 | B29: 06/06/2025 | C29: SP1 | D29: FRSD | E29: TH | F29: Sébastien Bonnefoi (P1H)/ Jean Michel Gabus P1X | G29: PC Av/Ar | H29: Front/Rear bumper | I29: P1X | J29: traité en PORO dépend du style | L29: 06/06/2025 PC P1X avec Air-Curtain | P29: o | Q29: CANCELED | S29: 0.25 | T29: 2 | U29: =T29*S29 -> 0.5 | V29: 1 | W29: 1 | X29: 1 | Y29: 1 | Z29: 1 | AA29: 1 | AB29: 1 | AC29: 1 | AD29: 1 | AE29: 1 | AF29: 1 | AG29: 1 | AH29: 1 | AI29: 1 | AJ29: 1 | AK29: 1 | AL29: 1 | AM29: 1 | AN29: 1 | AO29: 1 | AP29: 1 | AQ29: 1 | AR29: 1 | AS29: 1 | AV29: 1 | AW29: 1 | AX29: 1 | AY29: 1 | AZ29: 1 | BA29: 1
A30: 238 | B30: 46058 | C30: SP1 | D30: SWX/EE | E30: PTF | G30: Batterie 12V | H30: 12V battery | I30: Retour fournisseur en fonction de niv equipement | L30: 25/09/2024 : batterie EFR L2 sur niv1. La masse absolue dépend du fournisseur. 24/06/2024 : Retour fournisseur | P30: o | Q30: CANCELED | S30: 1 | T30: -0.4 | U30: =T30*S30 -> -0.4 | V30: 1 | W30: 1 | X30: 1 | Y30: 1 | Z30: 1 | AA30: 1 | AB30: 1 | AC30: 1 | AD30: 1 | AE30: 1 | AF30: 1 | AG30: 1 | AH30: 1 | AI30: 1 | AJ30: 1 | AK30: 1 | AL30: 1 | AM30: 1 | AN30: 1 | AO30: 1 | AP30: 1 | AS30: 1 | AW30: 1 | AX30: 1 | AY30: 1
A31: 245 | B31: 09/07/2024 | C31: SP1 | D31: PRS | E31: PWT | F31: ANTOINE SAINT MARCOUX | G31: Batterie RR/SR/HR | H31: HR battery | I31: 2 topics : Remove Fuse FO -0,3kg + Volume increase +1kg | L31: 09/07/2024 New | P31: o | Q31: IN PROGRESS | S31: 0.5 | T31: 0.7 | U31: =T31*S31 -> 0.35 | V31: 1 | W31: 1 | X31: 1 | Y31: 1 | Z31: 1 | AA31: 1 | AB31: 1 | AC31: 1 | AD31: 1 | AE31: 1 | AF31: 1 | AG31: 1 | AH31: 1 | AI31: 1 | AJ31: 1 | AK31: 1 | AL31: 1 | AM31: 1 | AN31: 1 | AS31: 1 | AW31: 1
A32: 248 | B32: 09/07/2024 | C32: SP1 | D32: PRS | E32: PWT | F32: ANTOINE SAINT MARCOUX | G32: Batterie HR | H32: HR battery | L32: 26/09/2025 Brackets : inc ds le STATUS 24/07/2025 2 sujets new : Bracket reinforct -2kg / Alu Busbar-3 (50%) 09/07/2024 New | P32: o | Q32: IN PROGRESS | S32: 0.5 | T32: -3 | U32: =T32*S32 -> -1.5 | V32: 1 | W32: 1 | X32: 1 | Y32: 1 | Z32: 1 | AA32: 1 | AB32: 1 | AC32: 1 | AD32: 1 | AE32: 1 | AF32: 1 | AG32: 1 | AH32: 1 | AI32: 1 | AJ32: 1 | AK32: 1 | AL32: 1 | AM32: 1 | AN32: 1 | AW32: 1
A33: 270 | B33: 08/04/2025 | C33: SP1 | D33: INT - SEATS/TRIMS | E33: TH | F33: HALIM | G33: Isolant Tapis | H33: Carpet insulation | I33: Insono Tapis pour le ThermalRunaway | J33: 24/06/2025 à vérifier plus tard | K33: SFM | L33: 08/04/2025 GT_calcul : Risque levé pour P1H-SR / Reste pour HR et XR 18/03/2025 Coord_STLAS : Pour P1h=7pièces => +1,5kg ; +4€ // Pour P1X +2pièces 19/11/2024 Risque SYNC3 (Estim 1,2*1,9 / 650gr/m²:GlassMAT™HTX isolation thermique et phonique des compartiments moteur) | P33: o | Q33: CANCELED | S33: 0.25 | T33: 1.482 | U33: =T33*S33 -> 0.3705 | V33: 1 | W33: 1 | X33: 1 | Y33: 1 | Z33: 1 | AA33: 1 | AB33: 1 | AC33: 1 | AD33: 1 | AE33: 1 | AF33: 1 | AG33: 1 | AH33: 1 | AI33: 1 | AJ33: 1 | AK33: 1 | AL33: 1 | AM33: 1 | AN33: 1 | AO33: 1 | AP33: 1 | AQ33: 1 | AR33: 1 | AS33: 1 | AV33: 1 | AW33: 1 | AX33: 1 | AY33: 1 | AZ33: 1 | BA33: 1
A34: 107b | B34: 08/10/2024 | C34: SP1 | D34: SWX/EE | E34: PTF | G34: Cable mode3 (7kW) | I34: Passage en option/APV | L34: 08/10/2024 : Proposition de mettre le cable en option lors de l'achat (forcée par défaut dans le cnfigurateur avec possibilité de le supprimer). 25/09/2024 : Interdit par la politique tech pour le passage APV (Julien Grand clerc / Alain Lefevre sollicités pour offi). 19/06/2024 : en cours sur SP1 et sur SP2 13/03/2024 ECMP > APV | P34: o | Q34: CANCELED | S34: 0.5 | T34: -2.6 | U34: =T34*S34 -> -1.3 | V34: 1 | W34: 1 | X34: 1 | Y34: 1 | Z34: 1 | AA34: 1 | AB34: 1 | AC34: 1 | AD34: 1 | AE34: 1 | AF34: 1 | AG34: 1 | AH34: 1 | AI34: 1 | AJ34: 1 | AK34: 1 | AL34: 1 | AM34: 1 | AN34: 1 | AO34: 1 | AP34: 1 | AQ34: 1 | AR34: 1 | AS34: 1 | AV34: 1 | AW34: 1 | AX34: 1 | AY34: 1 | AZ34: 1 | BA34: 1
A35: 188a | B35: 28/05/2025 | C35: SP1 | D35: FRSD | E35: TH | F35: Sébastien Bonnefoi (P1H)/ Jean Michel Gabus P1X | G35: Aile/Capot P1X | H35: style/brand | I35: Nvo STYLE | L35: 28/05/2025 CHANTIER MASSE : Nvo Styl, en attente design 25/04/2024 : pas de modif style => A annuler pour P1H. 27/03/2024 New WS S14 | P35: o | Q35: CANCELED | S35: 0.25 | T35: 0.5 | U35: =T35*S35 -> 0.125 | V35: 1 | W35: 1 | X35: 1 | Y35: 1 | Z35: 1 | AA35: 1 | AB35: 1 | AC35: 1 | AD35: 1 | AE35: 1 | AF35: 1 | AG35: 1 | AH35: 1 | AI35: 1 | AJ35: 1 | AK35: 1 | AL35: 1 | AM35: 1 | AN35: 1 | AO35: 1 | AP35: 1 | AQ35: 1 | AR35: 1 | AS35: 1 | AV35: 1 | AW35: 1 | AX35: 1 | AY35: 1 | AZ35: 1 | BA35: 1
A36: 45b | B36: 46058 | C36: SP1 | D36: PHES | E36: PTF | G36: Optimisation des supports PHES | H36: support optim | I36: STEP2 : Optimize thickness | L36: 11/09/2024 : Travaux en cours | P36: o | Q36: IN PROGRESS | S36: 0.25 | T36: -0.5 | U36: =T36*S36 -> -0.125 | V36: 1 | W36: 1 | X36: 1 | Y36: 1 | Z36: 1 | AA36: 1 | AB36: 1 | AC36: 1 | AD36: 1 | AE36: 1 | AF36: 1 | AG36: 1 | AH36: 1 | AI36: 1 | AJ36: 1 | AK36: 1 | AL36: 1 | AM36: 1 | AN36: 1 | AO36: 1 | AP36: 1 | AQ36: 1 | AR36: 1 | AS36: 1 | AT36: 1 | AU36: 1 | AV36: 1 | AW36: 1 | AX36: 1 | AY36: 1 | AZ36: 1 | BA36: 1
A37: 45c | B37: 46058 | C37: SP1 | D37: SWX/EE | E37: PTF | G37: SUPPORT MULTIFONCTION AR G BATTERIE TRACTION | H37: support optim | I37: STEP2 : Optimize thickness valeur initiale : 0,847 kg | L37: 09/12/2025 : Proposition de créer une diversité entre les versions AWD et FWD pour tous les HR | P37: o | Q37: IN PROGRESS | S37: 1 | T37: -0.45 | U37: =T37*S37 -> -0.45 | V37: 1 | W37: 1 | X37: 1 | Y37: 1 | Z37: 1 | AA37: 1 | AB37: 1 | AC37: 1 | AD37: 1 | AE37: 1 | AF37: 1 | AG37: 1 | AH37: 1 | AI37: 1 | AJ37: 1 | AK37: 1 | AL37: 1 | AM37: 1 | AN37: 1 | AO37: 1 | AP37: 1 | AS37: 1 | AW37: 1 | AX37: 1
A38: 92 | B38: 06/06/2025 | C38: SP1 | D38: DIW | E38: TH | F38: Filipe Goncalves (P1H)/ Cyrille P1X | G38: Portes | H38: BIW/ DIW process | I38: Impact masse demande DIR pour diminuer la diversité (ép. : dizaine supérieure) | J38: 06/02/2026LM Pas concerné | L38: 06/06/2025 Niveau de risk diminué à 25%, Final step : fin de SYNC3 04/11/2024 Décalage planning > Post Go_Calcul 12/07/2024 En attente des résultats SYNC3 21/03/2024 A valoriser suite aux résultats SYNC2 (voir avec RM) 14/03/2024 New / A décider avant engagement SYNC3 | P38: o | Q38: CANCELED | S38: 0.25 | T38: 1.2 | U38: =T38*S38 -> 0.3 | V38: 1 | W38: 1 | X38: 1 | Y38: 1 | Z38: 1 | AA38: 1 | AB38: 1 | AC38: 1 | AD38: 1 | AE38: 1 | AF38: 1 | AG38: 1 | AH38: 1 | AI38: 1 | AJ38: 1 | AK38: 1 | AL38: 1 | AM38: 1 | AN38: 1 | AO38: 1 | AP38: 1 | AQ38: 1 | AR38: 1 | AS38: 1 | AV38: 1 | AW38: 1 | AX38: 1 | AY38: 1 | AZ38: 1 | BA38: 1
A39: 93B | B39: 08/04/2025 | C39: SP1 | D39: BIW | E39: TH | F39: Franck Baillon (SP1)/ Cyrille P1X | G39: BIW : CHOC | H39: risk perfo | I39: Rft 3é voie | J39: Bilan Choc dira si on peut appliquer aussi | L39: 08/04/2025 Scénario choc tt SP1 : Dbl Aile AV & Rft Abv Cote HAB (+0,888kg) 03/09/2024 En attente travaux Base sur la 3ée voie … Synthèse idem P1H ! (0,5kg à 50%) 25/04/2024 : Suite choc frontal SYNC1 .Risque ajout raidisseu 13/03/2024 maj 01/02/2024 Ptf | P39: x | Q39: DECIDED | S39: 0.5 | T39: 0.888 | U39: =T39*S39 -> 0.444 | V39: 1 | W39: 1 | X39: 1 | Y39: 1 | Z39: 1 | AA39: 1 | AB39: 1 | AC39: 1 | AD39: 1 | AE39: 1 | AF39: 1 | AG39: 1 | AH39: 1 | AI39: 1 | AJ39: 1 | AK39: 1 | AL39: 1 | AM39: 1 | AN39: 1 | AO39: 1 | AP39: 1 | AQ39: 1 | AR39: 1 | AS39: 1 | AV39: 1 | AW39: 1 | AX39: 1 | AY39: 1 | AZ39: 1 | BA39: 1
B40: 45536 | C40: SPC_1 | D40: BIW | E40: TH | F40: FRANK BAILLON | G40: Doublure custode | H40: Lower quarter inner | I40: stratégie embout Mise en panoplie avec Upper rear inner quarter | J40: 06/10/2025 a reboucler avec l'embout - Mickael Ludovic DASNOIS | K40: DTM PM-CM | L40: 26/06/2025 a reboucler après hypothèse projet | M40: -400K€ | N40: 0.7 | P40: o | Q40: CANCELED | R40: TBD | S40: 0.5 | T40: 0.43 | U40: =T40*S40 -> 0.215 | V40: 1 | W40: 1 | X40: 1 | Y40: 1 | Z40: 1 | AA40: 1 | AB40: 1 | AC40: 1 | AD40: 1 | AE40: 1 | AF40: 1 | AG40: 1 | AH40: 1 | AI40: 1 | AJ40: 1 | AK40: 1 | AL40: 1 | AM40: 1 | AN40: 1 | AO40: 1 | AP40: 1 | AQ40: 1 | AR40: 1 | AS40: 1 | AT40: 1 | AU40: 1 | AV40: 1 | AW40: 1 | AX40: 1 | AY40: 1 | AZ40: 1 | BA40: 1
...

Sheet Feuil1
B3: Ajouter JEEP
B5: Sujet 1
B6: A mettre dans le PTF | C6: Volet P3U => 8 et 10kg d'impact masse du volet P3U vs. concept P1X remis aux dimensions P3U (Rodolphe).
B7: suppression du risk a voir avec adpatation | C7: Fuel tank => 40 (44, +1) et 45 (47, +0,5) HEV préssurisé / non préssurisé MHEV (TPC ?). Goulotte métal. Voir le réservoir de CMP annoncé à 9,3kg avec une capacité de 44kg
B8: dans le PTF | C8: Door module => -1,5kg, Marc Nespoulos
B9: dans le PTF | C9: Siège rang 2 => 40/20/40 P3U. 40/60. Masse 2,4.
B10: dans le PTF | C10: Magic handle si déclinaison. => 0,8
B11: A mettre dans le PTF | C11: 17'' => 235/60R17 sur les MHEV de J1X (=> J2U ? => P3U ?). => Adrien 4kg à confirmer
B12: A mettre dans le PTF | C12: Headlamp P3U. Proposition de déclinaison entry => -6kg
B13: A mettre dans le PTF | C13: Poutre répa arrière => 6,6kg sur P1X versus 3,7kg sur une Yaris Cross, 3,1 sur P21 pour Hybride
B14: A mettre dans le PTF | C14: Brake disk ald eDrum => 1,5kg ? Avec ajout park lock
B15: A mettre dans le PTF | C15: COI XV = -0,5kg
B16: A mettre dans le PTF | C16: update Nouveau point C Masse ?
B17: A mettre dans le PTF | C17: pivot alu
... B22: A mettre dans le PTF | C22: Volet plastique pour jeep
C23: Coffre entry peugeot ?
B24: A mettre dans le PTF | C24: Rear lamp T2 supp jeep
B25: RISK | C25: P2P pour JEEP = 2kg
B26: A mettre dans le PTF | C26: optim tapis XHEV / BEV =-1kg / BEV
B29: Sujet 2
B30: A mettre dans le PTF | C30: Niv 0 a evoquer
B32: Sujet 3
B33: dans le PTF | C33: process -4%
B35: Sujet 4
B36: recherche d'idée

Sheet TcD SPC
A1: P3U HR FWD | D1: P3U MHEV FWD | G1: P3U HEV FWD
A2: P3U HR 63 FWD€ | B2: 1 | D2: P3U MHEV FWD€ | E2: 1 | G2: P3U HEV FWD€ | H2: 1
A3: COTATION (*) | B3: IN PROGRESS | D3: COTATION (*) | E3: IN PROGRESS | G3: COTATION (*) | H3: IN PROGRESS
A5: Étiquettes de lignes | B5: Somme de Ponderated mass / Ratio (kg*%) | D5: Étiquettes de lignes | E5: Somme de Ponderated mass / Ratio (kg*%) | G5: Étiquettes de lignes | H5: Somme de Ponderated mass / Ratio (kg*%)
A6: PTF | B6: -4.715 | D6: PTF | E6: -16.80275 | G6: PTF | H6: -16.80275
A7: BCI_BODY | B7: -8.55 | D7: BCI_CHASSIS | E7: -1.3 | G7: BCI_CHASSIS | H7: -1.3
A8: BCI_CHASSIS | B8: 0 | D8: BIW | E8: -3.38775 | G8: BIW | H8: -3.38775
A9: BIW | B9: 4.2 | D9: PHES | E9: -9.125 | G9: PHES | H9: -9.125
A10: PHES | B10: 0.075 | D10: SWX/EE | E10: -2.99 | G10: SWX/EE | H10: -2.99
A11: SWX/EE | B11: -0.44 | D11: TH | E11: -33.495 | G11: PWT | H11: 1.7
A12: PWT | B12: -1.15 | D12: All | E12: -17.5 | G12: PRS | H12: 1.7
A13: PRS | B13: -1.15 | D13: BCI_BODY | E13: 0 | G13: TH | H13: -33.495
A14: TH | B14: -29.495 | D14: BCI_CHASSIS | E14: -4 | G14: All | H14: -17.5
A15: All | B15: -17.5 | D15: BIW | E15: -0.87 | G15: BCI_BODY | H15: 0
A16: BCI_BODY | B16: 0 | D16: DIW | E16: -1.5 | G16: BCI_CHASSIS | H16: -4
A17: BIW | B17: -0.87 | D17: FRSD | E17: -7.2 | G17: BIW | H17: -0.87
... A21: INT - SEATS/TRIMS | B21: -1.86 | D21: Total général | E21: -50.29775 | G21: INT - SEATS/TRIMS | H21: -1.86
A22: SWX/EE | B22: -0.4 | G22: SWX/EE | H22: -0.4
A23: Total général | B23: -35.36 | G23: Total général | H23: -48.59775
A33: J1X SR FWD | D33: J1X MHEV FWD | G33: J1X HEV FWD
A34: J1X SR FWD€ | B34: 1 | D34: J1X MHEV FWD€ | E34: 1 | G34: J1X HEV FWD€ | H34: 1
A35: COTATION (*) | B35: IN PROGRESS | D35: COTATION (*) | E35: IN PROGRESS | G35: COTATION (*) | H35: IN PROGRESS
A37: Étiquettes de lignes | B37: Somme de Ponderated mass / Ratio (kg*%) | D37: Étiquettes de lignes | E37: Somme de Ponderated mass / Ratio (kg*%) | G37: Étiquettes de lignes | H37: Somme de Ponderated mass / Ratio (kg*%)
A38: PTF | B38: -9.29 | D38: PTF | E38: -16.115 | G38: PTF | H38: -16.115
A39: BCI_BODY | B39: -8.925 | D39: BCI_CHASSIS | E39: -1.3 | G39: BCI_CHASSIS | H39: -1.3
A40: BCI_CHASSIS | B40: 0 | D40: BIW | E40: -2.7 | G40: BIW | H40: -2.7
A41: BIW | B41: 0 | D41: PHES | E41: -9.125 | G41: PHES | H41: -9.125
A42: PHES | B42: 0.075 | D42: SWX/EE | E42: -2.99 | G42: SWX/EE | H42: -2.99
A43: SWX/EE | B43: -0.44 | D43: TH | E43: -29.095 | G43: PWT | H43: 1.7
A44: PWT | B44: 0.35 | D44: All | E44: -17.5 | G44: PRS | H44: 1.7
A45: PRS | B45: 0.35 | D45: BCI_BODY | E45: 0 | G45: TH | H45: -28.955
A46: TH | B46: -24.955 | D46: BCI_CHASSIS | E46: -4 | G46: All | H46: -17.5
A47: All | B47: -17.5 | D47: BIW | E47: -0.87 | G47: BCI_BODY | H47: 0
A48: BCI_BODY | B48: 0 | D48: DIW | E48: -1.5 | G48: BCI_CHASSIS | H48: -4
A49: BIW | B49: -0.87 | D49: FRSD | E49: -2.7 | G49: BIW | H49: -0.87
... A53: INT - SEATS/TRIMS | B53: -1.86 | D53: Total général | E53: -45.21 | G53: INT - SEATS/TRIMS | H53: -1.86
A54: SWX/EE | B54: -0.4 | G54: SWX/EE | H54: -0.4
A55: Total général | B55: -33.895 | G55: Total général | H55: -43.37
A67: J2U HR FWD | D67: J2U MHEV FWD | G67: J2U HEV FWD
A68: J2U HR 63 FWD€ | B68: 1 | D68: J2U MHEV FWD | E68: 1 | G68: J2U HEV FWD | H68: 1
...

Sheet export SP1 S26
A1: Topic Nr | B1: Creation Date | C1: Responsible | D1: Functions | E1: BVH / PWT / Tophat | F1: Désignation : Ensemble / Piéces FR | G1: Désignation : Ensemble / Piéces ENG | H1: Description | I1: Comments BCI SP2 | J1: Date | K1: Mass comments (changes, dates, …) | L1: Invest impact | M1: TPC Impact (€) | N1: Next steps | O1: Decision expected for ? | P1: COTATION (*) | Q1: Priorization | R1: Confidence % | S1: Mass kg (*) | T1: Ponderated mass / Ratio (kg*%) | U1: O3H HR 63 FWD€ | V1: O3H XR 80 FWD€ | W1: O3H XR 80 AWD perfo € | X1: O3W 63 kWhu LFP FWD€ | Y1: O3W 80 kWhu NMx FWD€ | Z1: O3H MHEV FWD€ | AA1: O3W MHEV FWD€ | AB1: P3S HR 63 FWD€ | AC1: P3S XR 80 FWD€ | AD1: P3S XR 80 AWD perfo € | AE1: P3W 63 kWhu LFP FWD€ | AF1: P3W 80 kWhu NMx FWD€ | AG1: P3S MHEV FWD€ | AH1: P3WMHEV FWD€ | AI1: O1X HR 63 FWD€ | AJ1: O1X XR 80 FWD€ | AK1: O1X XR 80 AWD perfo € | AL1: O1X MHEV FWD€ | AM1: P1H MHEV | AN1: P1X MHEV
A2: 215 | B2: 45758 | C2: SP1 | D2: SWX/EE | E2: PTF | F2: Goulotte faisceaux moteur | G2: Optimisation | K2: 25/09/2024 : Compté dans le périmètre TH. 18/07/2024 : issu GT EE scope du 15/07/2024 | O2: o | P2: IN PROGRESS | Q2: TBD | R2: 0.5 | S2: 0.02 | T2: =S2*R2 -> 0.01 | U2: 1 | V2: 1 | W2: 1 | X2: 1 | Y2: 1 | Z2: 1 | AA2: 1 | AB2: 1 | AC2: 1 | AD2: 1 | AE2: 1 | AF2: 1 | AG2: 1 | AH2: 1 | AI2: 1 | AJ2: 1 | AK2: 1 | AL2: 1
A4: N° du sujet | B4: Date de mise à jour | C4: Métier (*) | D4: Métier (*) | E4: PTF/PRS/TH | F4: FR Désignation : Ensemble / Piéces | G4: Typologie : Raw Mat/Style/Process…. | H4: Description | K4: Commentaires masse tracer les changements apportés, par date | P4: COTATION (*) | R4: % confiance | S4: Masse kg (*)
A5: 54 | B5: 11/06/2025 | C5: SP1 | D5: INT - SEATS/TRIMS | E5: TH | F5: Assise Rg1 - Tissus | G5: optim design | H5: Retour frns | K5: 11/06/2025 Style non gélé , mais orientation en cours avec Tie down donc Potentiel a descendre a 25% [ald50%] 18/11/2024 Maj suite SYNC3 =>-0,8kg*50% (ald 25%*-0,2kg) 05/11/2024 Reporté 2025 25/09/2024 EN attente choirs frns => Fin Sept 11/07/2024 choix frns CW39 | P5: IN PROGRESS | R5: 0.25 | S5: -0.8 | T5: =S5*R5 -> -0.2
A6: 55 | B6: 11/06/2025 | C6: SP1 | D6: INT - SEATS/TRIMS | E6: TH | F6: Assise Rg2 - Tissus | G6: optim design | H6: Retour frns | K6: 11/06/2025 Style non gélé , mais orientation en cours avec Tie down donc Potentiel a descendre a 25% [ald 50%] 18/11/2024 Maj suite SYNC3=-0,6kg*50% (ald-0,65kg*25%) 05/11/2024 Reporté 2025 25/09/2024 EN attente choirs frns => Fin Sept 11/07/2024 choix frns CW39 | P6: IN PROGRESS | R6: 0.25 | S6: -0.6 | T6: =S6*R6 -> -0.15
A7: 92 | B7: 06/06/2025 | C7: SP1 | D7: DIW | E7: TH | F7: Portes | G7: BIW/ DIW process | H7: Impact masse demande DIR pour diminuer la diversité (ép. : dizaine supérieure) | K7: 06/06/2025 Niveau de risk diminué à 25%, Final step : fin de SYNC3 04/11/2024 Décalage planning > Post Go_Calcul 12/07/2024 En attente des résultats SYNC3 21/03/2024 A valoriser suite aux résultats SYNC2 (voir avec RM) 14/03/2024 New / A décider avant engagement SYNC3 | P7: IN PROGRESS | R7: 0.25 | S7: 1.2 | T7: =S7*R7 -> 0.3
A8: 105b | B8: 28/05/2025 | C8: SP1 | D8: BIW | E8: TH | F8: Optimass P1X | G8: optimass process | H8: Calculs : Choc Fr&Lat, R14 Rg2, NVH | K8: 28/05/2025 CHANTIER MASSE : A construire | P8: IN PROGRESS | R8: 0.5 | S8: -1.8 | T8: =S8*R8 -> -0.9
A9: 122 | B9: 27/06/2024 | C9: SP1 | D9: SWX/EE | E9: TH | F9: Faisceaux_LV | H9: Cross section optimization | K9: 27/06/2024 Estim à -0,3kg (-50%) 25/03/2024 A développer à l'aide des prochains plans faisceaux : X0 13/03/2024b New | P9: IN PROGRESS | R9: 0.5 | S9: -0.3 | T9: =S9*R9 -> -0.15
A10: 130 | B10: 15/11/2024 | C10: SP1 | D10: INT - PDB/CONSOLE | E10: TH | F10: PdB | G10: optim design | H10: Retour calcul SYNC2> SYNC3 | K10: 15/11/2024 Tjrs ouvert => calcul avec les SYNC3 05/09/2024 Retour calcul SYNC2 ok => Optim à étudier 06/06/2024 Besoin choix frns Fin Sept / En attente retour calcul SYNC2 14/03/2024 Selon process frn | P10: IN PROGRESS | R10: 0.25 | S10: -0.3 | T10: =S10*R10 -> -0.075
A11: 131 | B11: 01/04/2025 | C11: SP1 | D11: Door panel | E11: TH | F11: Panneau de porte | G11: style/brand | H11: Suppression Textile Fabric | K11: 01/04/2025 FOAM nécessaire pour process/frn. Et Risque d'ajout d'un tissu embossé sur Portes AV - Demande STYLE, TT niveau -(PTM/VSM) 15/11/2024 Suppression FOAM 14/03/2024 Line-up V9 | P11: IN PROGRESS | R11: 0.25 | S11: 0.1 | T11: =S11*R11 -> 0.025
A12: 132 | B12: 01/04/2025 | C12: SP1 | D12: INT - PDB/CONSOLE | E12: TH | F12: Pdb_suppression du foam sur les décors textiles | G12: style/brand | H12: suppression du foam sur les décors textiles | K12: 01/04/2025 Idem Pano Porte 20/09/2024 Passage en PT/VSM CW40 05/09/2024 A revoir avec Guillaume 14/03/2024 Line-up V9 | P12: IN PROGRESS | R12: 0.25 | S12: 0.1 | T12: =S12*R12 -> 0.025
A13: 136 | B13: 11/09/2024 | C13: SP1 | D13: INT - PDB/CONSOLE | E13: TH | F13: Pdb_Eclairage | G13: style/brand | H13: Suppression Ambient lighting - sur Mainstream | K13: 11/09/2024 Supp eclair écran(228g+40g) = Inscrit au plan coût /Supp ALCOVE (200g) : STd bye 05/09/2024 A revoir avec Guillaume 05/09/2024 : Ne concerne que ALCOVE / Sous écran : pas de contrainte / Ss facade aérateur : uniqt Niv3 06/06/2024 Si TT= RAS/ Si MeG besoin de obturateur ! 14/03/2024 dans l'alcove | P13: IN PROGRESS | R13: 0.25 | S13: -0.268 | T13: =S13*R13 -> -0.067
A14: 181 | B14: 11/02/2025 | C14: SP1 | D14: BCI_CHASSIS | E14: PTF | F14: Pedale frein | H14: Optimization apres award BATZ | K14: 11/02/2025 : A suivre lors des offi en juin. Design en cours. Risque de ne pas avoir de gain voire une augmentation de masse. passage de la piste à 0. 27/11/2024 : ECR lancé. impact masse à venir S49. 03/10/2024 : Itérations en cours avec NVH 28/08/2024 : Convergence NVH en cours. Solution a 1,2 kg (vs 1,5 kg) en cours. A voir avec Philippe pour bilan. 28/06/2024 : Bilan prestation à présenter 10/04/2024 : Reste à converger avec ACV 21/03/2024 : LHD seulement | P14: IN PROGRESS | R14: 1 | S14: 0 | T14: =S14*R14 -> 0
A15: 202 | B15: 11/06/2025 | C15: SP1 | D15: DIW | E15: TH | F15: Rft Choc LAT Porte AV | G15: BIW/ DIW process | H15: Embout à chaud PHS950 YS1500T => PHS1400-Y1800T et réduction épaisseur | K15: 11/06/2025 A ré-évaluer 04/11/2024 Idem post Go-Calcul SYNC3 08/07/2024 Retour calcul SYNC3 (Go calcul Nov => 2025?) Pièce en Embout à chaud | P15: IN PROGRESS | R15: 0.5 | S15: -0.1 | T15: =S15*R15 -> -0.05
A16: 203 | B16: 08/04/2025 | C16: SP1 | D16: BIW | E16: TH | F16: BIW Renfort montant baie + renfort pied avant | G16: BIW/ DIW process | H16: Embout à chaud :PHS950 YS1500T => PHS1400-Y1800T et réduction épaisseur | K16: 08/04/2025 Relance SAF 05/11/2024 A revoir avec SAF 03/09/2024 Synthèse Métier en cours 11/07/2024 Uniqt Rf Montant Baie, Maj eval à -0,34kg*100% (vs-0,8*25%) | P16: IN PROGRESS | R16: 1 | S16: -0.34 | T16: =S16*R16 -> -0.34
A17: 215 | B17: 25/09/2024 | C17: SP1 | D17: SWX/EE | E17: PTF | F17: Goulotte faisceaux moteur | H17: Optimisation | K17: 25/09/2024 : Compté dans le périmètre TH. 18/07/2024 : issu GT EE scope du 15/07/2024 | P17: IN PROGRESS | R17: 0.5 | S17: 0.02 | T17: =S17*R17 -> 0.01
A18: 224 | B18: 25/09/2024 | C18: SP1 | D18: ICDV | E18: TH | F18: Pneu | H18: Optim de masse 17" et 18" | K18: 25/09/2024 reporté S40 02/09/2024 besoin anayse VDYN 12/06/2024 New / attente retour frns | P18: IN PROGRESS | R18: 0.5 | S18: -1.2 | T18: =S18*R18 -> -0.6
A19: 233 | B19: 18/06/2024 | C19: SP1 | D19: INT - SEATS/TRIMS | E19: TH | F19: Insono | G19: optim design | H19: Insono Lat AV Console +10/20g Insono AR Console -50g Insono Lat CENT Console -100g Ins Collecteur AUVENT : New Ins. DEFLECTEUR EXTRACTEUR AIR : Supp Ins Passe de roue AR : New CALE PAVILLON : New | K19: 18/06/2024 Dossier RFQ : Masses sup | P19: IN PROGRESS | R19: 0.5 | S19: 0.3 | T19: =S19*R19 -> 0.15
A20: 234 | B20: 18/06/2024 | C20: SP1 | D20: INT - SEATS/TRIMS | E20: TH | F20: Garniture Raidisseur Pavillon | G20: optim design | H20: Dossier RFQ (obj masse) | K20: 18/06/2024 Dossier RFQ : Masses sup | P20: IN PROGRESS | R20: 0.5 | S20: 0.3 | T20: =S20*R20 -> 0.15
A21: 238 | C21: SP1 | D21: SWX/EE | E21: PTF | F21: Batterie 12V | H21: Retour fournisseur en fonction de niv equipement | K21: 25/09/2024 : batterie EFR L2 sur niv1. La masse absolue dépend du fournisseur. 24/06/2024 : Retour fournisseur | P21: IN PROGRESS | R21: 1 | S21: -0.4 | T21: =S21*R21 -> -0.4
A22: 245 | B22: 09/07/2024 | C22: SP1 | D22: PRS | E22: PWT | F22: Batterie RR/SR/HR | H22: 2 topics : Remove Fuse FO -0,3kg + Volume increase +1kg | K22: 09/07/2024 New | P22: IN PROGRESS | R22: 0.5 | S22: 0.7 | T22: =S22*R22 -> 0.35
A23: 248 | B23: 09/07/2024 | C23: SP1 | D23: PRS | E23: PWT | F23: Batterie HR | H23: 2 topics : Bracket reif +1kg / Aluminium busbars -0,6kg | K23: 09/07/2024 New | P23: IN PROGRESS | R23: 1 | S23: 0.68 | T23: =S23*R23 -> 0.68
A24: 254 | B24: 11/06/2025 | C24: SP1 | D24: DIW | E24: TH | F24: Porte AR : Rft | G24: optim design | H24: Remplacement / rft allégé | K24: 11/06/2025 ECR engagé => Publi en cours ; Passe à 100% / -1kg [50% ; -0,8kg] 04/11/2024 Revoir résult Choc Lat 03/09/2024 : GT_Presta CW35 / En attente résultat Side Crash SYNC2 | P24: IN PROGRESS | R24: 1 | S24: -1 | T24: =S24*R24 -> -1
A25: 107b | B25: 08/10/2024 | C25: SP1 | D25: SWX/EE | E25: PTF | F25: Cable mode3 (7kW) | H25: Passage en option/APV | K25: 08/10/2024 : Proposition de mettre le cable en option lors de l'achat (forcée par défaut dans le cnfigurateur avec possibilité de le supprimer). 25/09/2024 : Interdit par la politique tech pour le passage APV (Julien Grand clerc / Alain Lefevre sollicités pour offi). 19/06/2024 : en cours sur SP1 et sur SP2 13/03/2024 ECMP > APV | P25: IN PROGRESS | R25: 0.5 | S25: -2.6 | T25: =S25*R25 -> -1.3
A26: 188a | B26: 28/05/2025 | C26: SP1 | D26: FRSD | E26: TH | F26: Aile/Capot P1X | G26: style/brand | H26: Nvo STYLE | K26: 28/05/2025 CHANTIER MASSE : Nvo Styl, en attente design 25/04/2024 : pas de modif style => A annuler pour P1H. 27/03/2024 New WS S14 | P26: IN PROGRESS | R26: 0.25 | S26: 0.5 | T26: =S26*R26 -> 0.125
A27: 45b | B27: 11/09/2024 | C27: SP1 | D27: PHES | E27: PTF | F27: Optimisation des supports PHES | H27: STEP2 : Optimize thickness | K27: 11/09/2024 : Travaux en cours | P27: IN PROGRESS | R27: 1 | S27: -0.5 | T27: =S27*R27 -> -0.5
A28: 45c | B28: 06/03/2025 | C28: SP1 | D28: SWX/EE | E28: PTF | F28: Optimisation des supports EHE | H28: STEP2 : Optimize thickness valeur initiale : 0,847 kg | K28: 06/03/2025 : Presentation en PTM/VSM d'un modèle en plastique de 0,28 kg --> augmentation du gain à -0,57 kg 25/09/2024 : Fait parti du faisceau moteur | P28: IN PROGRESS | R28: 1 | S28: -0.567 | T28: =S28*R28 -> -0.567
A29: 45c | B29: 03/09/2024 | C29: SP1 | D29: BIW | E29: TH | F29: Panneau AR_P1X : ep.0,85 | H29: status=0,9 | K29: 03/09/2024 Retour Métier sur hypothèse Ref 13/03/2024 NVH constraint (P21:0,65) CW10 ref | P29: IN PROGRESS | R29: 1 | S29: -0.48 | T29: =S29*R29 -> -0.48
A30: 93B | B30: 08/04/2025 | C30: SP1 | D30: BIW | E30: TH | F30: BIW : CHOC | G30: risk perfo | H30: Rft 3é voie | K30: 08/04/2025 Scénario choc tt SP1 : Dbl Aile AV & Rft Abv Cote HAB (+0,888kg) 03/09/2024 En attente travaux Base sur la 3ée voie … Synthèse idem P1H ! (0,5kg à 50%) 25/04/2024 : Suite choc frontal SYNC1 .Risque ajout raidisseu 13/03/2024 maj 01/02/2024 Ptf | P30: IN PROGRESS | R30: 0.5 | S30: 0.888 | T30: =S30*R30 -> 0.444
A31: 95d | B31: 28/05/2025 | C31: SP1 | D31: BIW | E31: TH | F31: Coeff Num/Phys TH | G31: num/phys | H31: -2,5% (BIW=110kg) | K31: 28/05/2025 CHANTIER MASSE : Masse P1X | P31: IN PROGRESS | R31: 1 | S31: -2.75 | T31: =S31*R31 -> -2.75
A32: 95e | B32: 06/06/2025 | C32: SP1 | D32: FRSD | E32: TH | F32: Coeff Num/Phys TH | G32: num/phys | K32: 06/06/2025 A revoir si decision du volet Plastique 28/05/2025 CHANTIER MASSE : Masse P1X | P32: IN PROGRESS | R32: 1 | S32: -0.9 | T32: =S32*R32 -> -0.9
A33: 95f | B33: 28/05/2025 | C33: SP1 | D33: DIW | E33: TH | F33: Coeff Num/Phys TH | G33: num/phys | H33: Ratio RETEX Métier selon pièces | K33: 28/05/2025 CHANTIER MASSE : Masse P1X | P33: IN PROGRESS | R33: 1 | S33: -2.5 | T33: =S33*R33 -> -2.5
A34: 96b | B34: 07/06/2024 | C34: SP1 | D34: All | E34: TH | F34: DFNu -4% | K34: 07/06/2024 Proposition cotation RT RAL -4% 22/03/2024 A définir pour les DFNU | P34: IN PROGRESS | R34: 0.25 | S34: -4 | T34: =S34*R34 -> -1
A35: 99c | B35: 26/08/2024 | C35: SP1 | D35: PRS | E35: PWT | F35: Ens PWT HR + 11kW | H35: HR Bat / FWD S EDM / IDCM 11kW | K35: 26/08/2024 Status maj > Ptf en Risque => Echéance C-sample : date ? 08/07/2024 Mass updated CW27 / maj en cours | P35: IN PROGRESS | R35: 0.5 | S35: 1.8 | T35: =S35*R35 -> 0.9
A36: 9b | B36: 23/10/2024 | C36: SP1 | D36: BCI_BODY | E36: PTF | F36: OPTIMASSE phase 2 : Opti dessin | H36: Optimisation de dessin | K36: 23/10/2024 : idem 9a. 23/07/2024 : Mise à jour suite présentation métier BCI (S.Choppard) 26/03/2024 : Examiner la BOM pour consolider le chiffre. 27/11/2023 : prise en compte PF | P36: IN PROGRESS | R36: 1 | S36: -1 | T36: =S36*R36 -> -1
A37: 283 | B37: 11/02/2025 | C37: SP1 | D37: BCI_CHASSIS | E37: PTF | F37: Actionneur volant direction filaire (SBW uniquement) | H37: Optimisation fournisseur | K37: 11/02/2025 : Pb en collapse vu en simu qui risque d'augmenter la masse. Essai physique cette semaine à Turin. Existe une solution en simu qui resout le problème -> à chiffrer S08 + passage en VSM/PTM S07 pour valider ECR chez le fournisseur 7/25/2024 : GT presta S30 : Convergence presque à la cible avec une estimation masse à 7.3 kg ald 8 kg en cible. Il reste des implementation à faire mais probablement pas à la hauteur des +0.7 d'écart. | P37: IN PROGRESS | R37: 0.25 | S37: -0.7 | T37: =S37*R37 -> -0.175
A38: 284 | B38: 11/02/2025 | C38: SP1 | D38: BCI_CHASSIS | E38: PTF | F38: Actionneur volant direction filaire (SBW uniquement) | H38: Optimisation reponse en frequence | K38: 11/02/2025 : Solution fer à cheval choisie. Retour cette semaine pour la faisa. 03/10/2024 : Essai prévu S40 mais pb appro pièce. 28/08/2024 : Travail en cours sur la traverse PdB. Simu et essais en cours. Délai a voir avec Philippe Vannier et Olivier en GT Prestation. 7/25/2024 : GT presta S30 : Convergence presque à la cible avec une estimation masse à 7.3 kg ald 8 kg en cible. Il reste des implementation à faire mais probablement pas à la hauteur des +0.7 d'écart. | P38: IN PROGRESS | R38: 1 | S38: 0.3 | T38: =S38*R38 -> 0.3
A39: 287 | B39: 11/02/2025 | C39: SP1 | D39: BCI_BODY | E39: PTF | F39: Zone Brancard | K39: 11/02/2025 : Passage du sujet en VSM/PTM S07 pour décider. 03/12/2024 : GT conception : eval précise après calcul : estimation à +0,7 kg hors tablier (valable TT). Epaisseur tablier à passer en 0,9 ald 0,7 --> +0,9 kg (impact seulement sur P1H, P1X déjà en 0,9). 20/11/2024 : Pb de choc après reception MaJ modèles de choc. Dessin en cours, calcul d'ici 2 ou 3 semaines. | P39: IN PROGRESS | R39: 1 | S39: 0.5 | T39: =S39*R39 -> 0.5
A40: 255 | C40: SP1 | D40: PHES | E40: PTF | F40: Damper | G40: TPC | H40: Remove sur Chiller, TMM, Compresseur. | K40: 11/09/2024 : Piste TPC. Gains suivant essai NVH à venir. | P40: IN PROGRESS | R40: 0.5 | S40: -0.1 | T40: =S40*R40 -> -0.05
A41: 294b | B41: 06/06/2025 | C41: SP1 | D41: BIW | E41: TH | F41: Longeron | G41: optim design | H41: Reduction feuillure inf longeron | K41: 06/06/2025 A re-vérifer ! RISK ??? 11/02/2025 : A passer en RD suite accord de toutes les parties. 07/01/2025 : reduction de la hauteur de feuillure de 9mm (6mm sur TH) pour un gain de 0,540 kg (-0,35 kg sur PTF et -0,19 kg sur TH) | P41: IN PROGRESS | R41: 1 | S41: -0.19 | T41: =S41*R41 -> -0.19
...

Sheet GLOBAL PORTFOLIO
A1: COMMON PART | BM1: FREE COLUMN To be used from PPEs
AJ2: PROGRAM deployement
A3: UPDATE | B3: PROPOSAL | L3: Mass (kg) | O3: Costs | T3: IMPLEMENTATION CONFIDENCE | AF3: TIMING | AJ3: SPC
A4: LAST UPDATE | B4: Cluster (Idea origin) | C4: Num | D4: PTF/TH/PS | E4: System Description | F4: Subsystems Description | G4: SFS/eBOM/DECOUPAGE | H4: Metafunction OWNER/ LEADER (SSTM - métier) | I4: PFDI VSM | J4: PART | K4: LIGHTWEIGHT ACTION | L4: Mass (kg) | M4: STARTING abs Weight (kg) | N4: STARTING Material | O4: w/o Costs | P4: INV (k€) | Q4: R&D (k€) | R4: TPC (€) | S4: €/kg | T4: Process STATUS | U4: Implementation milestone (from forecast to status) | V4: CONFIDENCE LEVEL (SSTM & VSM ASSESSMENT) | W4: FEASIBILITY (SSTM) | X4: COMPLEXITY | Y4: PERFORMANCES | Z4: PACKAGING | AA4: COSTS | AB4: TIMING | AC4: ODM | AD4: CAD RELEASE | AE4: Action/ Notes | AF4: OPENING DATE | AG4: REVIEW for DECISION DATE | AH4: Day to review | AI4: LAST CALL MILESTONE | AJ4: ='Portefeuille SP2'!V14 -> O3H HR 63 FWD€ | AK4: ='Portefeuille SP2'!W14 -> O3H XR 80 FWD€ | AL4: ='Portefeuille SP2'!X14 -> O3H XR 80 AWD perfo € | AM4: ='Portefeuille SP2'!Y14 -> O3H MHEV FWD€ | AN4: ='Portefeuille SP2'!Z14 -> O3H HEV FWD€ | AO4: ='Portefeuille SP2'!AA14 -> O3W 63 kWhu LFP FWD€ | AP4: ='Portefeuille SP2'!AB14 -> O3W 80 kWhu NMx FWD€ | AQ4: ='Portefeuille SP2'!AC14 -> O3W MHEV FWD€ | ... BF4: ='Portefeuille SP2'!AR14 -> P3U HEV FWD€ | BG4: ='Portefeuille SP2'!#REF! -> #REF! | BH4: ='Portefeuille SP2'!#REF! -> #REF! | BI4: ='Portefeuille SP2'!#REF! -> #REF! | BJ4: ='Portefeuille SP2'!#REF! -> #REF! | BK4: ='Portefeuille SP2'!#REF! -> #REF!
A5: 43918 | B5: Workshop | C5: A01 | D5: TH | E5: Body | F5: Underbody | G5: 5SCC/ | H5: NAME XXX | I5: NAME XXX | J5: Mid Floor | K5: Thickness reductions 0,8mm -->0,7mm | L5: -3.4 | M5: 24 | N5: Steel | O5: X | T5: New Proposal | U5: SHRM | V5: HIGH | W5: V | X5: V | Y5: G | Z5: V | AA5: G | AB5: G | AC5: =IF(COUNTIF(W5,"OK")>0,"OK",(IF(COUNTIF(W5:AB5,"K")>0,"KO",(IF(COUNTIF(W5:AB5,"R")>0,"R",(IF(COUNTIF(W5:AB5,"G")>0,"G",(IF(COUNTIF(W5:AB5,"V")>0,"V","-"))))))))) -> G | AF5: 45483 | AG5: 45514 | AH5: =IFERROR(DAYS360(TODAY(),AG5),"TBD") -> -626 | AI5: CM | AL5: 1 | AV5: 1 | BF5: 1
A6: 43918 | B6: Workshop | D6: PTF | G6: Multi | H6: A.SALESSE | I6: L.Perrugia | J6: Underbody | L6: -7 | N6: Steel | S6: -1.5 | T6: Under investigation (IN BEST P) | AF6: 45257 | AI6: S37
A7: 43918
A8: ='Portefeuille SP2'!B15 -> 45632 | B8: ='Portefeuille SP2'!Q15 -> CANCELED | D8: ='Portefeuille SP2'!E15 -> TH | E8: =LEFT(J8,3) -> BIW | F8: =MID(J8, 4, 20) | G8: ='Portefeuille SP2'!C15 -> SPC_1 | H8: ='Portefeuille SP2'!F15 -> MICHAEL BORE | J8: ='Portefeuille SP2'!D15 -> BIW | K8: ='Portefeuille SP2'!H15 -> activ spoiler | L8: ='Portefeuille SP2'!U15 -> 3.2 | P8: ='Portefeuille SP2'!M15 -> 0 | R8: ='Portefeuille SP2'!N15 -> 0 | T8: ='Portefeuille SP2'!R15 -> TBD | U8: ='Portefeuille SP2'!K15 -> 0 | V8: ='Portefeuille SP2'!S15 -> 0.8 | AE8: ='Portefeuille SP2'!J15 -> 06/10/2025 sujet à supprimer car pas d'active Spoiler sur le projet SPC_1 | AJ8: ='Portefeuille SP2'!V15 -> 1 | AK8: ='Portefeuille SP2'!W15 -> 1 | AL8: ='Portefeuille SP2'!X15 -> 1 | AM8: ='Portefeuille SP2'!Y15 -> 1 | AN8: ='Portefeuille SP2'!Z15 -> 1 | AO8: ='Portefeuille SP2'!AA15 -> 1 | AP8: ='Portefeuille SP2'!AB15 -> 1 | AQ8: ='Portefeuille SP2'!AC15 -> 1 | ... BF8: ='Portefeuille SP2'!AR15 -> 1 | BG8: ='Portefeuille SP2'!#REF! -> #REF! | BH8: ='Portefeuille SP2'!#REF! -> #REF! | BI8: ='Portefeuille SP2'!#REF! -> #REF! | BJ8: ='Portefeuille SP2'!#REF! -> #REF! | BK8: ='Portefeuille SP2'!#REF! -> #REF! | BM8: ='Portefeuille SP2'!L15 -> 0
A9: ='Portefeuille SP2'!B16 -> 20/06/2025 | B9: ='Portefeuille SP2'!Q16 -> CANCELED | D9: ='Portefeuille SP2'!E16 -> TH | E9: =LEFT(J9,3) -> FRS | F9: =MID(J9, 4, 20) -> D | G9: ='Portefeuille SP2'!C16 -> SP1 | H9: ='Portefeuille SP2'!F16 -> Sébastien Bonnefoi (P1H)/ Jean Michel Gabus P1X | J9: ='Portefeuille SP2'!D16 -> FRSD | K9: ='Portefeuille SP2'!H16 -> style/brand | L9: ='Portefeuille SP2'!U16 -> 2.2 | P9: ='Portefeuille SP2'!M16 -> 0 | R9: ='Portefeuille SP2'!N16 -> 0 | T9: ='Portefeuille SP2'!R16 -> 0 | U9: ='Portefeuille SP2'!K16 -> 0 | V9: ='Portefeuille SP2'!S16 -> 1 | AE9: ='Portefeuille SP2'!J16 -> Stratégie projet | AJ9: ='Portefeuille SP2'!V16 -> 1 | AK9: ='Portefeuille SP2'!W16 -> 1 | AL9: ='Portefeuille SP2'!X16 -> 1 | AM9: ='Portefeuille SP2'!Y16 -> 1 | AN9: ='Portefeuille SP2'!Z16 -> 1 | AO9: ='Portefeuille SP2'!AA16 -> 1 | AP9: ='Portefeuille SP2'!AB16 -> 1 | AQ9: ='Portefeuille SP2'!AC16 -> 1 | ... BF9: ='Portefeuille SP2'!AR16 -> 1 | BG9: ='Portefeuille SP2'!#REF! -> #REF! | BH9: ='Portefeuille SP2'!#REF! -> #REF! | BI9: ='Portefeuille SP2'!#REF! -> #REF! | BJ9: ='Portefeuille SP2'!#REF! -> #REF! | BK9: ='Portefeuille SP2'!#REF! -> #REF! | BM9: ='Portefeuille SP2'!L16 -> 20/06/2025 Retour frns : Proj MS+1,2kg / PC MS+1kg 28/05/2025 à 50% suite 1er retour frns du Proj / En attente info du PC 06/05/2025 passe à 75% 22/04/2025 RD _S16 : Choix Concept Proj (3 parts)_01353_25_00247 24/03/2025 Impact nvo Style_Feu déporté
A10: ='Portefeuille SP2'!#REF! -> #REF! | B10: ='Portefeuille SP2'!#REF! -> #REF! | D10: ='Portefeuille SP2'!#REF! -> #REF! | E10: =LEFT(J10,3) -> #REF! | F10: =MID(J10, 4, 20) -> #REF! | G10: ='Portefeuille SP2'!#REF! -> #REF! | H10: ='Portefeuille SP2'!#REF! -> #REF! | J10: ='Portefeuille SP2'!#REF! -> #REF! | K10: ='Portefeuille SP2'!#REF! -> #REF! | L10: ='Portefeuille SP2'!#REF! -> #REF! | P10: ='Portefeuille SP2'!#REF! -> #REF! | R10: ='Portefeuille SP2'!#REF! -> #REF! | T10: ='Portefeuille SP2'!#REF! -> #REF! | U10: ='Portefeuille SP2'!#REF! -> #REF! | V10: ='Portefeuille SP2'!#REF! -> #REF! | AE10: ='Portefeuille SP2'!#REF! -> #REF! | AJ10: ='Portefeuille SP2'!#REF! -> #REF! | AK10: ='Portefeuille SP2'!#REF! -> #REF! | AL10: ='Portefeuille SP2'!#REF! -> #REF! | AM10: ='Portefeuille SP2'!#REF! -> #REF! | AN10: ='Portefeuille SP2'!#REF! -> #REF! | AO10: ='Portefeuille SP2'!#REF! -> #REF! | AP10: ='Portefeuille SP2'!#REF! -> #REF! | AQ10: ='Portefeuille SP2'!#REF! -> #REF! | ... BK10: ='Portefeuille SP2'!#REF! -> #REF! | BM10: ='Portefeuille SP2'!#REF! -> #REF!
A11: ='Portefeuille SP2'!B17 -> 45536 | B11: ='Portefeuille SP2'!Q17 -> DECIDED | D11: ='Portefeuille SP2'!E17 -> TH | E11: =LEFT(J11,3) -> BIW | F11: =MID(J11, 4, 20) | G11: ='Portefeuille SP2'!C17 -> SPC_1 | H11: ='Portefeuille SP2'!F17 -> MICHAEL BORE | J11: ='Portefeuille SP2'!D17 -> BIW | K11: ='Portefeuille SP2'!H17 -> hood Pantographe | L11: ='Portefeuille SP2'!U17 -> 1 | P11: ='Portefeuille SP2'!M17 -> 350 | R11: ='Portefeuille SP2'!N17 -> 8.5 | T11: ='Portefeuille SP2'!R17 -> TBD | U11: ='Portefeuille SP2'!K17 -> PM | V11: ='Portefeuille SP2'!S17 -> 1 | AE11: ='Portefeuille SP2'!J17 -> 10/10/2025 référence projet col de cygne, mais demande PEDPRO de Pantographe 11/10/2024 QCTP Pantograh hood hinge =>https://docinfogroupe.stellantis.com/ead/doc/ref.21007_24_00151/v.vc/fiche | AJ11: ='Portefeuille SP2'!V17 -> 1 | AK11: ='Portefeuille SP2'!W17 -> 1 | AL11: ='Portefeuille SP2'!X17 -> 1 | AM11: ='Portefeuille SP2'!Y17 -> 1 | AN11: ='Portefeuille SP2'!Z17 -> 1 | AO11: ='Portefeuille SP2'!AA17 -> 1 | AP11: ='Portefeuille SP2'!AB17 -> 1 | AQ11: ='Portefeuille SP2'!AC17 -> 1 | ... BF11: ='Portefeuille SP2'!AR17 -> 1 | BG11: ='Portefeuille SP2'!#REF! -> #REF! | BH11: ='Portefeuille SP2'!#REF! -> #REF! | BI11: ='Portefeuille SP2'!#REF! -> #REF! | BJ11: ='Portefeuille SP2'!#REF! -> #REF! | BK11: ='Portefeuille SP2'!#REF! -> #REF! | BM11: ='Portefeuille SP2'!L17 -> 0
A12: ='Portefeuille SP2'!B18 -> 45536 | B12: ='Portefeuille SP2'!Q18 -> DECIDED | D12: ='Portefeuille SP2'!E18 -> TH | E12: =LEFT(J12,3) -> BIW | F12: =MID(J12, 4, 20) | G12: ='Portefeuille SP2'!C18 -> SPC_1 | H12: ='Portefeuille SP2'!F18 -> MICHAEL BORE | J12: ='Portefeuille SP2'!D18 -> BIW | K12: ='Portefeuille SP2'!H18 -> front & rear bumper | L12: ='Portefeuille SP2'!U18 -> 0.82 | P12: ='Portefeuille SP2'!M18 -> 0 | R12: ='Portefeuille SP2'!N18 -> (-6) | T12: ='Portefeuille SP2'!R18 -> TBD | U12: ='Portefeuille SP2'!K18 -> 0 | V12: ='Portefeuille SP2'!S18 -> 1 | AE12: ='Portefeuille SP2'!J18 -> 06/10/2025 Pas de PORO | AJ12: ='Portefeuille SP2'!V18 -> 1 | AK12: ='Portefeuille SP2'!W18 -> 1 | AL12: ='Portefeuille SP2'!X18 -> 1 | AM12: ='Portefeuille SP2'!Y18 -> 1 | AN12: ='Portefeuille SP2'!Z18 -> 1 | AO12: ='Portefeuille SP2'!AA18 -> 1 | AP12: ='Portefeuille SP2'!AB18 -> 1 | AQ12: ='Portefeuille SP2'!AC18 -> 1 | ... BF12: ='Portefeuille SP2'!AR18 -> 1 | BG12: ='Portefeuille SP2'!#REF! -> #REF! | BH12: ='Portefeuille SP2'!#REF! -> #REF! | BI12: ='Portefeuille SP2'!#REF! -> #REF! | BJ12: ='Portefeuille SP2'!#REF! -> #REF! | BK12: ='Portefeuille SP2'!#REF! -> #REF! | BM12: ='Portefeuille SP2'!L18 -> 0
A13: ='Portefeuille SP2'!B19 -> 45813 | B13: ='Portefeuille SP2'!Q19 -> CANCELED | D13: ='Portefeuille SP2'!E19 -> TH | E13: =LEFT(J13,3) -> INT | F13: =MID(J13, 4, 20) -> - PDB/CONSOLE | G13: ='Portefeuille SP2'!C19 -> SP1 | H13: ='Portefeuille SP2'!F19 -> FREDERIC BRUNIER | J13: ='Portefeuille SP2'!D19 -> INT - PDB/CONSOLE | K13: ='Portefeuille SP2'!H19 -> Dashboard/Upper console | L13: ='Portefeuille SP2'!U19 -> 0.75 | P13: ='Portefeuille SP2'!M19 -> 0 | R13: ='Portefeuille SP2'!N19 -> 0 | T13: ='Portefeuille SP2'!R19 -> 0 | U13: ='Portefeuille SP2'!K19 -> 0 | V13: ='Portefeuille SP2'!S19 -> 0.75 | AE13: ='Portefeuille SP2'!J19 -> CP P1H Sébastien Dupuis 24/06/2025 à confirmer avec Sébastien car attente panneau SYNC5 et MAJ de la masse | AJ13: ='Portefeuille SP2'!V19 -> 1 | AK13: ='Portefeuille SP2'!W19 -> 1 | AL13: ='Portefeuille SP2'!X19 -> 1 | AM13: ='Portefeuille SP2'!Y19 -> 1 | AN13: ='Portefeuille SP2'!Z19 -> 1 | AO13: ='Portefeuille SP2'!AA19 -> 1 | AP13: ='Portefeuille SP2'!AB19 -> 1 | AQ13: ='Portefeuille SP2'!AC19 -> 1 | ... BF13: ='Portefeuille SP2'!AR19 -> 1 | BG13: ='Portefeuille SP2'!#REF! -> #REF! | BH13: ='Portefeuille SP2'!#REF! -> #REF! | BI13: ='Portefeuille SP2'!#REF! -> #REF! | BJ13: ='Portefeuille SP2'!#REF! -> #REF! | BK13: ='Portefeuille SP2'!#REF! -> #REF! | BM13: ='Portefeuille SP2'!L19 -> 05/06/2025  Planche de Bord : +0.280 kg / Console UPPER : +0.147 kg et +0.260 kg
A14: ='Portefeuille SP2'!B20 -> 01/04/2025 | B14: ='Portefeuille SP2'!Q20 -> CANCELED | D14: ='Portefeuille SP2'!E20 -> TH | E14: =LEFT(J14,3) -> Doo | F14: =MID(J14, 4, 20) -> r panel | G14: ='Portefeuille SP2'!C20 -> SP1 | H14: ='Portefeuille SP2'!F20 -> FREDERIC BRUNIER | J14: ='Portefeuille SP2'!D20 -> Door panel | K14: ='Portefeuille SP2'!H20 -> style/brand | L14: ='Portefeuille SP2'!U20 -> 0.025 | P14: ='Portefeuille SP2'!M20 -> 0 | R14: ='Portefeuille SP2'!N20 -> 0 | T14: ='Portefeuille SP2'!R20 -> 0 | U14: ='Portefeuille SP2'!K20 -> 0 | V14: ='Portefeuille SP2'!S20 -> 0.25 | AE14: ='Portefeuille SP2'!J20 -> CP P1H Sébastien Dupuis 23/06/25 LM : Vu avec Frédéric refusé par SP1 - A confirmer pour SPC | AJ14: ='Portefeuille SP2'!V20 -> 1 | AK14: ='Portefeuille SP2'!W20 -> 1 | AL14: ='Portefeuille SP2'!X20 -> 1 | AM14: ='Portefeuille SP2'!Y20 -> 1 | AN14: ='Portefeuille SP2'!Z20 -> 1 | AO14: ='Portefeuille SP2'!AA20 -> 1 | AP14: ='Portefeuille SP2'!AB20 -> 1 | AQ14: ='Portefeuille SP2'!AC20 -> 1 | ... BF14: ='Portefeuille SP2'!AR20 -> 1 | BG14: ='Portefeuille SP2'!#REF! -> #REF! | BH14: ='Portefeuille SP2'!#REF! -> #REF! | BI14: ='Portefeuille SP2'!#REF! -> #REF! | BJ14: ='Portefeuille SP2'!#REF! -> #REF! | BK14: ='Portefeuille SP2'!#REF! -> #REF! | BM14: ='Portefeuille SP2'!L20 -> 01/04/2025 FOAM nécessaire pour process/frn. Et Risque d'ajout d'un tissu embossé sur Portes AV - Demande STYLE, TT niveau -(PTM/VSM) 15/11/2024 Suppression FOAM 14/03/2024 Line-up V9
A15: ='Portefeuille SP2'!B21 -> 01/04/2025 | B15: ='Portefeuille SP2'!Q21 -> CANCELED | D15: ='Portefeuille SP2'!E21 -> TH | E15: =LEFT(J15,3) -> INT | F15: =MID(J15, 4, 20) -> - PDB/CONSOLE | G15: ='Portefeuille SP2'!C21 -> SP1 | H15: ='Portefeuille SP2'!F21 -> FREDERIC BRUNIER | J15: ='Portefeuille SP2'!D21 -> INT - PDB/CONSOLE | K15: ='Portefeuille SP2'!H21 -> style/brand | L15: ='Portefeuille SP2'!U21 -> 0.025 | P15: ='Portefeuille SP2'!M21 -> 0 | R15: ='Portefeuille SP2'!N21 -> 0 | T15: ='Portefeuille SP2'!R21 -> 0 | U15: ='Portefeuille SP2'!K21 -> 0 | V15: ='Portefeuille SP2'!S21 -> 0.25 | AE15: ='Portefeuille SP2'!J21 -> CP P1H Sébastien Dupuis 23/06/25 LM : Vu avec Frédéric refusé par SP1 - A confirmer pour SPC | AJ15: ='Portefeuille SP2'!V21 -> 1 | AK15: ='Portefeuille SP2'!W21 -> 1 | AL15: ='Portefeuille SP2'!X21 -> 1 | AM15: ='Portefeuille SP2'!Y21 -> 1 | AN15: ='Portefeuille SP2'!Z21 -> 1 | AO15: ='Portefeuille SP2'!AA21 -> 1 | AP15: ='Portefeuille SP2'!AB21 -> 1 | AQ15: ='Portefeuille SP2'!AC21 -> 1 | ... BF15: ='Portefeuille SP2'!AR21 -> 1 | BG15: ='Portefeuille SP2'!#REF! -> #REF! | BH15: ='Portefeuille SP2'!#REF! -> #REF! | BI15: ='Portefeuille SP2'!#REF! -> #REF! | BJ15: ='Portefeuille SP2'!#REF! -> #REF! | BK15: ='Portefeuille SP2'!#REF! -> #REF! | BM15: ='Portefeuille SP2'!L21 -> 01/04/2025 Idem Pano Porte 20/09/2024 Passage en PT/VSM CW40 05/09/2024 A revoir avec Guillaume 14/03/2024 Line-up V9
A16: ='Portefeuille SP2'!B22 -> 45546 | B16: ='Portefeuille SP2'!Q22 -> DECIDED | D16: ='Portefeuille SP2'!E22 -> TH | E16: =LEFT(J16,3) -> BIW | F16: =MID(J16, 4, 20) | G16: ='Portefeuille SP2'!C22 -> SPC_1 | H16: ='Portefeuille SP2'!F22 -> FRANK BAILLON | J16: ='Portefeuille SP2'!D22 -> BIW | K16: ='Portefeuille SP2'!H22 -> B pillar inner | L16: ='Portefeuille SP2'!U22 -> 0.75 | P16: ='Portefeuille SP2'!M22 -> -350K€ | R16: ='Portefeuille SP2'!N22 -> 2 | T16: ='Portefeuille SP2'!R22 -> TBD | U16: ='Portefeuille SP2'!K22 -> DTM PM-CM | V16: ='Portefeuille SP2'!S22 -> 0.5 | AE16: ='Portefeuille SP2'!J22 -> 06/10/2025 a reboucler avec l'embout - Mickael Ludovic DASNOIS | AJ16: ='Portefeuille SP2'!V22 -> 1 | AK16: ='Portefeuille SP2'!W22 -> 1 | AL16: ='Portefeuille SP2'!X22 -> 1 | AM16: ='Portefeuille SP2'!Y22 -> 1 | AN16: ='Portefeuille SP2'!Z22 -> 1 | AO16: ='Portefeuille SP2'!AA22 -> 1 | AP16: ='Portefeuille SP2'!AB22 -> 1 | AQ16: ='Portefeuille SP2'!AC22 -> 1 | ... BF16: ='Portefeuille SP2'!AR22 -> 1 | BG16: ='Portefeuille SP2'!#REF! -> #REF! | BH16: ='Portefeuille SP2'!#REF! -> #REF! | BI16: ='Portefeuille SP2'!#REF! -> #REF! | BJ16: ='Portefeuille SP2'!#REF! -> #REF! | BK16: ='Portefeuille SP2'!#REF! -> #REF! | BM16: ='Portefeuille SP2'!L22 -> 26/06/2025 a reboucler après hypothèse projet
A17: ='Portefeuille SP2'!B23 -> 46058 | B17: ='Portefeuille SP2'!Q23 -> IN PROGRESS | D17: ='Portefeuille SP2'!E23 -> PTF | E17: =LEFT(J17,3) -> BCI | F17: =MID(J17, 4, 20) -> _CHASSIS | G17: ='Portefeuille SP2'!C23 -> SP1 | H17: ='Portefeuille SP2'!F23 -> 0 | J17: ='Portefeuille SP2'!D23 -> BCI_CHASSIS | K17: ='Portefeuille SP2'!H23 -> Rr axle ML | L17: ='Portefeuille SP2'!U23 -> 0 | P17: ='Portefeuille SP2'!M23 -> 0 | R17: ='Portefeuille SP2'!N23 -> 0 | T17: ='Portefeuille SP2'!R23 -> 0 | U17: ='Portefeuille SP2'!K23 -> 0 | V17: ='Portefeuille SP2'!S23 -> 0.75 | AE17: ='Portefeuille SP2'!J23 -> 0 | AJ17: ='Portefeuille SP2'!V23 -> 1 | AK17: ='Portefeuille SP2'!W23 -> 1 | AL17: ='Portefeuille SP2'!X23 -> 1 | AM17: ='Portefeuille SP2'!Y23 -> 1 | AN17: ='Portefeuille SP2'!Z23 -> 1 | AO17: ='Portefeuille SP2'!AA23 -> 1 | AP17: ='Portefeuille SP2'!AB23 -> 1 | AQ17: ='Portefeuille SP2'!AC23 -> 1 | ... BF17: ='Portefeuille SP2'!AR23 -> 1 | BG17: ='Portefeuille SP2'!#REF! -> #REF! | BH17: ='Portefeuille SP2'!#REF! -> #REF! | BI17: ='Portefeuille SP2'!#REF! -> #REF! | BJ17: ='Portefeuille SP2'!#REF! -> #REF! | BK17: ='Portefeuille SP2'!#REF! -> #REF! | BM17: ='Portefeuille SP2'!L23 -> 27/11/2025 : Présentation en VSM/PTM. Gain important en Aero, mais cout important (+3,5€). Besoin à confirmer après essai, pas en ref en ce moment. Nouvelle estimation à 0,5 kg 03/10/2025 : Aero demande des écrans sur les bras du ML. Demande à confirmer.
A18: ='Portefeuille SP2'!B24 -> 11/06/2025 | B18: ='Portefeuille SP2'!Q24 -> CANCELED | D18: ='Portefeuille SP2'!E24 -> TH | E18: =LEFT(J18,3) -> DIW | F18: =MID(J18, 4, 20) | G18: ='Portefeuille SP2'!C24 -> SP1 | H18: ='Portefeuille SP2'!F24 -> Filipe Goncalves (P1H)/ Cyrille P1X | J18: ='Portefeuille SP2'!D24 -> DIW | K18: ='Portefeuille SP2'!H24 -> BIW/ DIW process | L18: ='Portefeuille SP2'!U24 -> -0.05 | P18: ='Portefeuille SP2'!M24 -> 0 | R18: ='Portefeuille SP2'!N24 -> 0 | T18: ='Portefeuille SP2'!R24 -> 0 | U18: ='Portefeuille SP2'!K24 -> 0 | V18: ='Portefeuille SP2'!S24 -> 0.5 | AE18: ='Portefeuille SP2'!J24 -> déjà intégré dans la BDD SP2 - ligne à supprimer | AJ18: ='Portefeuille SP2'!V24 -> 1 | AK18: ='Portefeuille SP2'!W24 -> 1 | AL18: ='Portefeuille SP2'!X24 -> 1 | AM18: ='Portefeuille SP2'!Y24 -> 1 | AN18: ='Portefeuille SP2'!Z24 -> 1 | AO18: ='Portefeuille SP2'!AA24 -> 1 | AP18: ='Portefeuille SP2'!AB24 -> 1 | AQ18: ='Portefeuille SP2'!AC24 -> 1 | ... BF18: ='Portefeuille SP2'!AR24 -> 1 | BG18: ='Portefeuille SP2'!#REF! -> #REF! | BH18: ='Portefeuille SP2'!#REF! -> #REF! | BI18: ='Portefeuille SP2'!#REF! -> #REF! | BJ18: ='Portefeuille SP2'!#REF! -> #REF! | BK18: ='Portefeuille SP2'!#REF! -> #REF! | BM18: ='Portefeuille SP2'!L24 -> 02/07/2025 CANCELLED : Ep.mini déjà atteinte (chgt de matière possible mais aurait nécessité une dimintution d'épasisseur) 11/06/2025 A ré-évaluer 04/11/2024 Idem post Go-Calcul SYNC3 08/07/2024 Retour calcul SYNC3 (Go calcul Nov => 2025?) Pièce en Embout à chaud
A19: ='Portefeuille SP2'!B25 -> 45536 | B19: ='Portefeuille SP2'!Q25 -> DECIDED | D19: ='Portefeuille SP2'!E25 -> TH | E19: =LEFT(J19,3) -> BIW | F19: =MID(J19, 4, 20) | G19: ='Portefeuille SP2'!C25 -> SPC_1 | H19: ='Portefeuille SP2'!F25 -> MICHAEL BORE | J19: ='Portefeuille SP2'!D25 -> BIW | K19: ='Portefeuille SP2'!H25 -> Rear quarter GLASS | L19: ='Portefeuille SP2'!U25 -> 0.75 | P19: ='Portefeuille SP2'!M25 -> 690K€ | R19: ='Portefeuille SP2'!N25 -> 27.1 | T19: ='Portefeuille SP2'!R25 -> TBD | U19: ='Portefeuille SP2'!K25 -> PM-CM | V19: ='Portefeuille SP2'!S25 -> 0.75 | AE19: ='Portefeuille SP2'!J25 -> 06/10/2025 OK pour P3U et J2U | AJ19: ='Portefeuille SP2'!V25 -> 1 | AK19: ='Portefeuille SP2'!W25 -> 1 | AL19: ='Portefeuille SP2'!X25 -> 1 | AM19: ='Portefeuille SP2'!Y25 -> 1 | AN19: ='Portefeuille SP2'!Z25 -> 1 | AO19: ='Portefeuille SP2'!AA25 -> 1 | AP19: ='Portefeuille SP2'!AB25 -> 1 | AQ19: ='Portefeuille SP2'!AC25 -> 1 | ... BF19: ='Portefeuille SP2'!AR25 -> 1 | BG19: ='Portefeuille SP2'!#REF! -> #REF! | BH19: ='Portefeuille SP2'!#REF! -> #REF! | BI19: ='Portefeuille SP2'!#REF! -> #REF! | BJ19: ='Portefeuille SP2'!#REF! -> #REF! | BK19: ='Portefeuille SP2'!#REF! -> #REF! | BM19: ='Portefeuille SP2'!L25 -> 26/06/2025 a reboucler après hypothèse projet
